<sdf version='1.6'>
  <world name='default'>
    <light name='sun' type='directional'>
      <cast_shadows>1</cast_shadows>
      <pose frame=''>0 0 10 0 -0 0</pose>
      <diffuse>0.8 0.8 0.8 1</diffuse>
      <specular>0.2 0.2 0.2 1</specular>
      <attenuation>
        <range>1000</range>
        <constant>0.9</constant>
        <linear>0.01</linear>
        <quadratic>0.001</quadratic>
      </attenuation>
      <direction>-0.5 0.1 -0.9</direction>
    </light>
    <model name='ground_plane'>
      <static>1</static>
      <link name='link'>
        <collision name='collision'>
          <geometry>
            <plane>
              <normal>0 0 1</normal>
              <size>100 100</size>
            </plane>
          </geometry>
          <surface>
            <contact>
              <collide_bitmask>65535</collide_bitmask>
              <ode/>
            </contact>
            <friction>
              <ode>
                <mu>100</mu>
                <mu2>50</mu2>
              </ode>
              <torsional>
                <ode/>
              </torsional>
            </friction>
            <bounce/>
          </surface>
          <max_contacts>10</max_contacts>
        </collision>
        <visual name='visual'>
          <cast_shadows>0</cast_shadows>
          <geometry>
            <plane>
              <normal>0 0 1</normal>
              <size>100 100</size>
            </plane>
          </geometry>
          <material>
            <script>
              <uri>file://media/materials/scripts/gazebo.material</uri>
              <name>Gazebo/Grey</name>
            </script>
          </material>
        </visual>
        <self_collide>0</self_collide>
        <kinematic>0</kinematic>
      </link>
    </model>
    <gravity>0 0 -9.8</gravity>
    <magnetic_field>6e-06 2.3e-05 -4.2e-05</magnetic_field>
    <atmosphere type='adiabatic'/>
    <physics name='default_physics' default='0' type='ode'>
      <max_step_size>0.001</max_step_size>
      <real_time_factor>1</real_time_factor>
      <real_time_update_rate>1000</real_time_update_rate>
    </physics>
    <scene>
      <ambient>0.4 0.4 0.4 1</ambient>
      <background>0.7 0.7 0.7 1</background>
      <shadows>1</shadows>
    </scene>
    <spherical_coordinates>
      <surface_model>EARTH_WGS84</surface_model>
      <latitude_deg>0</latitude_deg>
      <longitude_deg>0</longitude_deg>
      <elevation>0</elevation>
      <heading_deg>0</heading_deg>
    </spherical_coordinates>
    <model name='grape_robot'>
      <link name='base_footprint'>
        <pose frame=''>0 0 0 0 -0 0</pose>
        <inertial>
          <pose frame=''>-0.01846 -0 0.585257 0 -0 0</pose>
          <mass>1968.12</mass>
          <inertia>
            <ixx>412.557</ixx>
            <ixy>6.59125e-15</ixy>
            <ixz>22.0399</ixz>
            <iyy>1425.59</iyy>
            <iyz>5.84217e-15</iyz>
            <izz>1737.02</izz>
          </inertia>
        </inertial>
        <collision name='base_footprint_collision'>
          <pose frame=''>0 0 0 0 -0 0</pose>
          <geometry>
            <box>
              <size>0.001 0.001 0.001</size>
            </box>
          </geometry>
          <max_contacts>10</max_contacts>
          <surface>
            <contact>
              <ode/>
            </contact>
            <bounce/>
            <friction>
              <torsional>
                <ode/>
              </torsional>
              <ode/>
            </friction>
          </surface>
        </collision>
        <collision name='base_footprint_fixed_joint_lump__car_base_link_collision_1'>
          <pose frame=''>0 0 0.3 0 -0 0</pose>
          <geometry>
            <mesh>
              <scale>1 1 1</scale>
              <uri>/home/samleong/project_ws/src/grape_robot_description/meshes/car_base_link.STL</uri>
            </mesh>
          </geometry>
          <surface>
            <contact>
              <ode/>
            </contact>
            <friction>
              <ode/>
              <torsional>
                <ode/>
              </torsional>
            </friction>
            <bounce/>
          </surface>
          <max_contacts>10</max_contacts>
        </collision>
        <collision name='base_footprint_fixed_joint_lump__arm1_base_link_collision_2'>
          <pose frame=''>-0.4 0 0.75 0 -0 1.5708</pose>
          <geometry>
            <mesh>
              <scale>1 1 1</scale>
              <uri>/home/samleong/project_ws/src/grape_robot_description/meshes/arm1_base_link.STL</uri>
            </mesh>
          </geometry>
          <surface>
            <contact>
              <ode/>
            </contact>
            <friction>
              <ode/>
              <torsional>
                <ode/>
              </torsional>
            </friction>
            <bounce/>
          </surface>
          <max_contacts>10</max_contacts>
        </collision>
        <collision name='base_footprint_fixed_joint_lump__arm2_base_link_collision_3'>
          <pose frame=''>0.9 0 0.75 0 -0 1.5708</pose>
          <geometry>
            <mesh>
              <scale>1 1 1</scale>
              <uri>/home/samleong/project_ws/src/grape_robot_description/meshes/arm2_base_link.STL</uri>
            </mesh>
          </geometry>
          <surface>
            <contact>
              <ode/>
            </contact>
            <friction>
              <ode/>
              <torsional>
                <ode/>
              </torsional>
            </friction>
            <bounce/>
          </surface>
          <max_contacts>10</max_contacts>
        </collision>
        <collision name='base_footprint_fixed_joint_lump__basket_link_collision_4'>
          <pose frame=''>-1.2 0 0.75 0 -0 0</pose>
          <geometry>
            <mesh>
              <scale>1 1 1</scale>
              <uri>/home/samleong/project_ws/src/grape_robot_description/meshes/basket_link.STL</uri>
            </mesh>
          </geometry>
          <surface>
            <contact>
              <ode/>
            </contact>
            <friction>
              <ode/>
              <torsional>
                <ode/>
              </torsional>
            </friction>
            <bounce/>
          </surface>
          <max_contacts>10</max_contacts>
        </collision>
        <collision name='base_footprint_fixed_joint_lump__hokuyo_collision_5'>
          <pose frame=''>1.45 0 0.83 0 -0 0</pose>
          <geometry>
            <box>
              <size>0.1 0.1 0.1</size>
            </box>
          </geometry>
          <surface>
            <contact>
              <ode/>
            </contact>
            <friction>
              <ode/>
              <torsional>
                <ode/>
              </torsional>
            </friction>
            <bounce/>
          </surface>
          <max_contacts>10</max_contacts>
        </collision>
        <visual name='base_footprint_visual'>
          <pose frame=''>0 0 0 0 -0 0</pose>
          <geometry>
            <box>
              <size>0.001 0.001 0.001</size>
            </box>
          </geometry>
        </visual>
        <visual name='base_footprint_fixed_joint_lump__car_base_link_visual_1'>
          <pose frame=''>0 0 0.3 0 -0 0</pose>
          <geometry>
            <mesh>
              <scale>1 1 1</scale>
              <uri>/home/samleong/project_ws/src/grape_robot_description/meshes/car_base_link.STL</uri>
            </mesh>
          </geometry>
          <material>
            <script>
              <name>Gazebo/Blue</name>
              <uri>file://media/materials/scripts/gazebo.material</uri>
            </script>
          </material>
        </visual>
        <visual name='base_footprint_fixed_joint_lump__arm1_base_link_visual_2'>
          <pose frame=''>-0.4 0 0.75 0 -0 1.5708</pose>
          <geometry>
            <mesh>
              <scale>1 1 1</scale>
              <uri>/home/samleong/project_ws/src/grape_robot_description/meshes/arm1_base_link.STL</uri>
            </mesh>
          </geometry>
          <material>
            <script>
              <name>Gazebo/Green</name>
              <uri>file://media/materials/scripts/gazebo.material</uri>
            </script>
          </material>
        </visual>
        <visual name='base_footprint_fixed_joint_lump__arm2_base_link_visual_3'>
          <pose frame=''>0.9 0 0.75 0 -0 1.5708</pose>
          <geometry>
            <mesh>
              <scale>1 1 1</scale>
              <uri>/home/samleong/project_ws/src/grape_robot_description/meshes/arm2_base_link.STL</uri>
            </mesh>
          </geometry>
          <material>
            <script>
              <name>Gazebo/OrangeTransparent</name>
              <uri>file://media/materials/scripts/gazebo.material</uri>
            </script>
          </material>
        </visual>
        <visual name='base_footprint_fixed_joint_lump__basket_link_visual_4'>
          <pose frame=''>-1.2 0 0.75 0 -0 0</pose>
          <geometry>
            <mesh>
              <scale>1 1 1</scale>
              <uri>/home/samleong/project_ws/src/grape_robot_description/meshes/basket_link.STL</uri>
            </mesh>
          </geometry>
          <material>
            <script>
              <name>Gazebo/Orange</name>
              <uri>file://media/materials/scripts/gazebo.material</uri>
            </script>
          </material>
        </visual>
        <visual name='base_footprint_fixed_joint_lump__hokuyo_visual_5'>
          <pose frame=''>1.45 0 0.83 0 -0 0</pose>
          <geometry>
            <mesh>
              <scale>1 1 1</scale>
              <uri>/home/samleong/project_ws/src/grape_robot_description/meshes/hokuyo.dae</uri>
            </mesh>
          </geometry>
          <material>
            <script>
              <uri>__default__</uri>
              <name>__default__</name>
            </script>
          </material>
        </visual>
        <velocity_decay/>
        <velocity_decay/>
        <velocity_decay/>
        <velocity_decay/>
        <gravity>1</gravity>
        <velocity_decay/>
        <sensor name='head_hokuyo_sensor' type='ray'>
          <visualize>0</visualize>
          <update_rate>40</update_rate>
          <ray>
            <scan>
              <horizontal>
                <samples>720</samples>
                <resolution>1</resolution>
                <min_angle>-1.5708</min_angle>
                <max_angle>1.5708</max_angle>
              </horizontal>
              <vertical>
                <samples>1</samples>
                <min_angle>0</min_angle>
                <max_angle>0</max_angle>
              </vertical>
            </scan>
            <range>
              <min>0.1</min>
              <max>30</max>
              <resolution>0.01</resolution>
            </range>
            <noise>
              <type>gaussian</type>
              <mean>0</mean>
              <stddev>0.01</stddev>
            </noise>
          </ray>
          <plugin name='gazebo_ros_head_hokuyo_controller' filename='libgazebo_ros_laser.so'>
            <topicName>/grape_robot/laser/scan</topicName>
            <frameName>hokuyo</frameName>
            <robotNamespace>/</robotNamespace>
          </plugin>
          <pose frame=''>1.45 0 0.83 0 -0 0</pose>
        </sensor>
        <self_collide>0</self_collide>
        <kinematic>0</kinematic>
      </link>
      <link name='arm1_link1'>
        <pose frame=''>-0.4 0 0.82 0 -0 1.5708</pose>
        <inertial>
          <pose frame=''>0 0 0.138894 0 -0 0</pose>
          <mass>14.7707</mass>
          <inertia>
            <ixx>0.176856</ixx>
            <ixy>7.7315e-19</ixy>
            <ixz>1.98597e-18</ixz>
            <iyy>0.188513</iyy>
            <iyz>0</iyz>
            <izz>0.122105</izz>
          </inertia>
        </inertial>
        <collision name='arm1_link1_collision'>
          <pose frame=''>0 0 0 0 -0 0</pose>
          <geometry>
            <mesh>
              <scale>1 1 1</scale>
              <uri>/home/samleong/project_ws/src/grape_robot_description/meshes/arm1_link1.STL</uri>
            </mesh>
          </geometry>
          <surface>
            <contact>
              <ode/>
            </contact>
            <friction>
              <ode/>
              <torsional>
                <ode/>
              </torsional>
            </friction>
            <bounce/>
          </surface>
          <max_contacts>10</max_contacts>
        </collision>
        <visual name='arm1_link1_visual'>
          <pose frame=''>0 0 0 0 -0 0</pose>
          <geometry>
            <mesh>
              <scale>1 1 1</scale>
              <uri>/home/samleong/project_ws/src/grape_robot_description/meshes/arm1_link1.STL</uri>
            </mesh>
          </geometry>
          <material>
            <script>
              <name>Gazebo/Green</name>
              <uri>file://media/materials/scripts/gazebo.material</uri>
            </script>
          </material>
        </visual>
        <gravity>1</gravity>
        <velocity_decay/>
        <self_collide>0</self_collide>
        <kinematic>0</kinematic>
      </link>
      <joint name='arm1_joint1' type='revolute'>
        <child>arm1_link1</child>
        <parent>base_footprint</parent>
        <axis>
          <xyz>0 0 1</xyz>
          <limit>
            <lower>-1e+16</lower>
            <upper>1e+16</upper>
          </limit>
          <dynamics>
            <spring_reference>0</spring_reference>
            <spring_stiffness>0</spring_stiffness>
          </dynamics>
          <use_parent_model_frame>1</use_parent_model_frame>
        </axis>
      </joint>
      <link name='arm1_link2'>
        <pose frame=''>-0.4525 -0 1.12 1.5708 -0 1.5708</pose>
        <inertial>
          <pose frame=''>0.6 0 0.0525 0 -0 0</pose>
          <mass>38.0892</mass>
          <inertia>
            <ixx>0.248336</ixx>
            <ixy>5.96438e-19</ixy>
            <ixz>-4.74238e-16</ixz>
            <iyy>4.55188</iyy>
            <iyz>-1.6418e-17</iyz>
            <izz>4.44527</izz>
          </inertia>
        </inertial>
        <collision name='arm1_link2_collision'>
          <pose frame=''>0 0 0 0 -0 0</pose>
          <geometry>
            <mesh>
              <scale>1 1 1</scale>
              <uri>/home/samleong/project_ws/src/grape_robot_description/meshes/arm1_link2.STL</uri>
            </mesh>
          </geometry>
          <surface>
            <contact>
              <ode/>
            </contact>
            <friction>
              <ode/>
              <torsional>
                <ode/>
              </torsional>
            </friction>
            <bounce/>
          </surface>
          <max_contacts>10</max_contacts>
        </collision>
        <visual name='arm1_link2_visual'>
          <pose frame=''>0 0 0 0 -0 0</pose>
          <geometry>
            <mesh>
              <scale>1 1 1</scale>
              <uri>/home/samleong/project_ws/src/grape_robot_description/meshes/arm1_link2.STL</uri>
            </mesh>
          </geometry>
          <material>
            <script>
              <name>Gazebo/Green</name>
              <uri>file://media/materials/scripts/gazebo.material</uri>
            </script>
          </material>
        </visual>
        <gravity>1</gravity>
        <velocity_decay/>
        <self_collide>0</self_collide>
        <kinematic>0</kinematic>
      </link>
      <joint name='arm1_joint2' type='revolute'>
        <child>arm1_link2</child>
        <parent>arm1_link1</parent>
        <axis>
          <xyz>-1 -4e-06 4e-06</xyz>
          <limit>
            <lower>-3.14</lower>
            <upper>0</upper>
            <effort>1000</effort>
            <velocity>10</velocity>
          </limit>
          <dynamics>
            <spring_reference>0</spring_reference>
            <spring_stiffness>0</spring_stiffness>
          </dynamics>
          <use_parent_model_frame>1</use_parent_model_frame>
        </axis>
      </joint>
      <link name='arm1_link3'>
        <pose frame=''>-0.400004 1.2 1.12 1.5708 -0 1.5708</pose>
        <inertial>
          <pose frame=''>0.6 0 0 0 -0 0</pose>
          <mass>15.8952</mass>
          <inertia>
            <ixx>0.033752</ixx>
            <ixy>1.13292e-16</ixy>
            <ixz>-1.34294e-17</ixz>
            <iyy>2.14536</iyy>
            <iyz>1.54653e-18</iyz>
            <izz>2.14991</izz>
          </inertia>
        </inertial>
        <collision name='arm1_link3_collision'>
          <pose frame=''>0 0 0 0 -0 0</pose>
          <geometry>
            <mesh>
              <scale>1 1 1</scale>
              <uri>/home/samleong/project_ws/src/grape_robot_description/meshes/arm1_link3.STL</uri>
            </mesh>
          </geometry>
          <surface>
            <contact>
              <ode/>
            </contact>
            <friction>
              <ode/>
              <torsional>
                <ode/>
              </torsional>
            </friction>
            <bounce/>
          </surface>
          <max_contacts>10</max_contacts>
        </collision>
        <visual name='arm1_link3_visual'>
          <pose frame=''>0 0 0 0 -0 0</pose>
          <geometry>
            <mesh>
              <scale>1 1 1</scale>
              <uri>/home/samleong/project_ws/src/grape_robot_description/meshes/arm1_link3.STL</uri>
            </mesh>
          </geometry>
          <material>
            <script>
              <name>Gazebo/Green</name>
              <uri>file://media/materials/scripts/gazebo.material</uri>
            </script>
          </material>
        </visual>
        <gravity>1</gravity>
        <velocity_decay/>
        <self_collide>0</self_collide>
        <kinematic>0</kinematic>
      </link>
      <joint name='arm1_joint3' type='revolute'>
        <child>arm1_link3</child>
        <parent>arm1_link2</parent>
        <axis>
          <xyz>-1 -4e-06 4e-06</xyz>
          <limit>
            <lower>-2.4</lower>
            <upper>2.4</upper>
            <effort>1000</effort>
            <velocity>10</velocity>
          </limit>
          <dynamics>
            <spring_reference>0</spring_reference>
            <spring_stiffness>0</spring_stiffness>
          </dynamics>
          <use_parent_model_frame>1</use_parent_model_frame>
        </axis>
      </joint>
      <link name='arm1_link4'>
        <pose frame=''>-0.452509 2.4 1.12 1.5708 -0 1.5708</pose>
        <inertial>
          <pose frame=''>0.115302 0 0.0525 0 -0 0</pose>
          <mass>2.62488</mass>
          <inertia>
            <ixx>0.00962569</ixx>
            <ixy>2.90721e-09</ixy>
            <ixz>7.23028e-08</ixz>
            <iyy>0.0145549</iyy>
            <iyz>2.14765e-08</iyz>
            <izz>0.0137689</izz>
          </inertia>
        </inertial>
        <collision name='arm1_link4_collision'>
          <pose frame=''>0 0 0 0 -0 0</pose>
          <geometry>
            <mesh>
              <scale>1 1 1</scale>
              <uri>/home/samleong/project_ws/src/grape_robot_description/meshes/arm1_link4.STL</uri>
            </mesh>
          </geometry>
          <surface>
            <contact>
              <ode/>
            </contact>
            <friction>
              <ode/>
              <torsional>
                <ode/>
              </torsional>
            </friction>
            <bounce/>
          </surface>
          <max_contacts>10</max_contacts>
        </collision>
        <visual name='arm1_link4_visual'>
          <pose frame=''>0 0 0 0 -0 0</pose>
          <geometry>
            <mesh>
              <scale>1 1 1</scale>
              <uri>/home/samleong/project_ws/src/grape_robot_description/meshes/arm1_link4.STL</uri>
            </mesh>
          </geometry>
          <material>
            <script>
              <name>Gazebo/Turquoise</name>
              <uri>file://media/materials/scripts/gazebo.material</uri>
            </script>
          </material>
        </visual>
        <gravity>1</gravity>
        <velocity_decay/>
        <self_collide>0</self_collide>
        <kinematic>0</kinematic>
      </link>
      <joint name='arm1_joint4' type='revolute'>
        <child>arm1_link4</child>
        <parent>arm1_link3</parent>
        <axis>
          <xyz>-1 -4e-06 4e-06</xyz>
          <limit>
            <lower>-1.57</lower>
            <upper>1.57</upper>
            <effort>100</effort>
            <velocity>10</velocity>
          </limit>
          <dynamics>
            <spring_reference>0</spring_reference>
            <spring_stiffness>0</spring_stiffness>
          </dynamics>
          <use_parent_model_frame>1</use_parent_model_frame>
        </axis>
      </joint>
      <link name='grip_leftlink'>
        <pose frame=''>-0.450009 2.58 1.135 -3.14159 -4e-06 -3.14159</pose>
        <inertial>
          <pose frame=''>0.06662 0.014855 0.015 0 -0 0</pose>
          <mass>0.19814</mass>
          <inertia>
            <ixx>7.83981e-05</ixx>
            <ixy>-0.000114504</ixy>
            <ixz>-1.41743e-20</ixz>
            <iyy>0.000455719</iyy>
            <iyz>-8.68895e-21</iyz>
            <izz>0.000504397</izz>
          </inertia>
        </inertial>
        <collision name='grip_leftlink_collision'>
          <pose frame=''>0 0 0 0 -0 0</pose>
          <geometry>
            <mesh>
              <scale>1 1 1</scale>
              <uri>/home/samleong/project_ws/src/grape_robot_description/meshes/grip_leftlink.STL</uri>
            </mesh>
          </geometry>
          <surface>
            <contact>
              <ode/>
            </contact>
            <friction>
              <ode/>
              <torsional>
                <ode/>
              </torsional>
            </friction>
            <bounce/>
          </surface>
          <max_contacts>10</max_contacts>
        </collision>
        <visual name='grip_leftlink_visual'>
          <pose frame=''>0 0 0 0 -0 0</pose>
          <geometry>
            <mesh>
              <scale>1 1 1</scale>
              <uri>/home/samleong/project_ws/src/grape_robot_description/meshes/grip_leftlink.STL</uri>
            </mesh>
          </geometry>
          <material>
            <script>
              <name>Gazebo/Red</name>
              <uri>file://media/materials/scripts/gazebo.material</uri>
            </script>
          </material>
        </visual>
        <gravity>1</gravity>
        <velocity_decay/>
        <self_collide>0</self_collide>
        <kinematic>0</kinematic>
      </link>
      <joint name='grip_leftjoint' type='revolute'>
        <child>grip_leftlink</child>
        <parent>arm1_link4</parent>
        <axis>
          <xyz>-4e-06 -4e-06 -1</xyz>
          <limit>
            <lower>0</lower>
            <upper>1.57</upper>
            <effort>50</effort>
            <velocity>10</velocity>
          </limit>
          <dynamics>
            <spring_reference>0</spring_reference>
            <spring_stiffness>0</spring_stiffness>
          </dynamics>
          <use_parent_model_frame>1</use_parent_model_frame>
        </axis>
      </joint>
      <link name='grip_rightlink'>
        <pose frame=''>-0.35001 2.58 1.105 -4e-06 4e-06 0</pose>
        <inertial>
          <pose frame=''>0.06662 0.014855 0.015 0 -0 0</pose>
          <mass>0.19814</mass>
          <inertia>
            <ixx>7.83981e-05</ixx>
            <ixy>-0.000114504</ixy>
            <ixz>6.83773e-21</ixz>
            <iyy>0.000455719</iyy>
            <iyz>-2.22153e-21</iyz>
            <izz>0.000504397</izz>
          </inertia>
        </inertial>
        <collision name='grip_rightlink_collision'>
          <pose frame=''>0 0 0 0 -0 0</pose>
          <geometry>
            <mesh>
              <scale>1 1 1</scale>
              <uri>/home/samleong/project_ws/src/grape_robot_description/meshes/grip_rightlink.STL</uri>
            </mesh>
          </geometry>
          <surface>
            <contact>
              <ode/>
            </contact>
            <friction>
              <ode/>
              <torsional>
                <ode/>
              </torsional>
            </friction>
            <bounce/>
          </surface>
          <max_contacts>10</max_contacts>
        </collision>
        <visual name='grip_rightlink_visual'>
          <pose frame=''>0 0 0 0 -0 0</pose>
          <geometry>
            <mesh>
              <scale>1 1 1</scale>
              <uri>/home/samleong/project_ws/src/grape_robot_description/meshes/grip_rightlink.STL</uri>
            </mesh>
          </geometry>
          <material>
            <script>
              <name>Gazebo/Red</name>
              <uri>file://media/materials/scripts/gazebo.material</uri>
            </script>
          </material>
        </visual>
        <gravity>1</gravity>
        <velocity_decay/>
        <self_collide>0</self_collide>
        <kinematic>0</kinematic>
      </link>
      <joint name='grip_rightjoint' type='revolute'>
        <child>grip_rightlink</child>
        <parent>arm1_link4</parent>
        <axis>
          <xyz>-4e-06 -4e-06 -1</xyz>
          <limit>
            <lower>-1.57</lower>
            <upper>0</upper>
            <effort>50</effort>
            <velocity>10</velocity>
          </limit>
          <dynamics>
            <spring_reference>0</spring_reference>
            <spring_stiffness>0</spring_stiffness>
          </dynamics>
          <use_parent_model_frame>1</use_parent_model_frame>
        </axis>
      </joint>
      <link name='arm2_link1'>
        <pose frame=''>0.9 0 0.82 0 -0 1.5708</pose>
        <inertial>
          <pose frame=''>0 0 0.138894 0 -0 0</pose>
          <mass>14.7707</mass>
          <inertia>
            <ixx>0.176856</ixx>
            <ixy>7.7315e-19</ixy>
            <ixz>2.53182e-18</ixz>
            <iyy>0.188513</iyy>
            <iyz>-2.11758e-19</iyz>
            <izz>0.122105</izz>
          </inertia>
        </inertial>
        <collision name='arm2_link1_collision'>
          <pose frame=''>0 0 0 0 -0 0</pose>
          <geometry>
            <mesh>
              <scale>1 1 1</scale>
              <uri>/home/samleong/project_ws/src/grape_robot_description/meshes/arm2_link1.STL</uri>
            </mesh>
          </geometry>
          <surface>
            <contact>
              <ode/>
            </contact>
            <friction>
              <ode/>
              <torsional>
                <ode/>
              </torsional>
            </friction>
            <bounce/>
          </surface>
          <max_contacts>10</max_contacts>
        </collision>
        <visual name='arm2_link1_visual'>
          <pose frame=''>0 0 0 0 -0 0</pose>
          <geometry>
            <mesh>
              <scale>1 1 1</scale>
              <uri>/home/samleong/project_ws/src/grape_robot_description/meshes/arm2_link1.STL</uri>
            </mesh>
          </geometry>
          <material>
            <script>
              <name>Gazebo/OrangeTransparent</name>
              <uri>file://media/materials/scripts/gazebo.material</uri>
            </script>
          </material>
        </visual>
        <gravity>1</gravity>
        <velocity_decay/>
        <self_collide>0</self_collide>
        <kinematic>0</kinematic>
      </link>
      <joint name='arm2_joint1' type='revolute'>
        <child>arm2_link1</child>
        <parent>base_footprint</parent>
        <axis>
          <xyz>0 0 1</xyz>
          <limit>
            <lower>-1e+16</lower>
            <upper>1e+16</upper>
          </limit>
          <dynamics>
            <spring_reference>0</spring_reference>
            <spring_stiffness>0</spring_stiffness>
          </dynamics>
          <use_parent_model_frame>1</use_parent_model_frame>
        </axis>
      </joint>
      <link name='arm2_link2'>
        <pose frame=''>0.8475 -0 1.12 1.5708 -0 1.5708</pose>
        <inertial>
          <pose frame=''>0.6 0 0.0525 0 -0 0</pose>
          <mass>38.0892</mass>
          <inertia>
            <ixx>0.248336</ixx>
            <ixy>2.40838e-17</ixy>
            <ixz>-8.23093e-16</ixz>
            <iyy>4.55188</iyy>
            <iyz>-1.01049e-17</iyz>
            <izz>4.44527</izz>
          </inertia>
        </inertial>
        <collision name='arm2_link2_collision'>
          <pose frame=''>0 0 0 0 -0 0</pose>
          <geometry>
            <mesh>
              <scale>1 1 1</scale>
              <uri>/home/samleong/project_ws/src/grape_robot_description/meshes/arm2_link2.STL</uri>
            </mesh>
          </geometry>
          <surface>
            <contact>
              <ode/>
            </contact>
            <friction>
              <ode/>
              <torsional>
                <ode/>
              </torsional>
            </friction>
            <bounce/>
          </surface>
          <max_contacts>10</max_contacts>
        </collision>
        <visual name='arm2_link2_visual'>
          <pose frame=''>0 0 0 0 -0 0</pose>
          <geometry>
            <mesh>
              <scale>1 1 1</scale>
              <uri>/home/samleong/project_ws/src/grape_robot_description/meshes/arm2_link2.STL</uri>
            </mesh>
          </geometry>
          <material>
            <script>
              <name>Gazebo/OrangeTransparent</name>
              <uri>file://media/materials/scripts/gazebo.material</uri>
            </script>
          </material>
        </visual>
        <gravity>1</gravity>
        <velocity_decay/>
        <self_collide>0</self_collide>
        <kinematic>0</kinematic>
      </link>
      <joint name='arm2_joint2' type='revolute'>
        <child>arm2_link2</child>
        <parent>arm2_link1</parent>
        <axis>
          <xyz>-1 0 4e-06</xyz>
          <limit>
            <lower>-3.14</lower>
            <upper>0</upper>
            <effort>1000</effort>
            <velocity>10</velocity>
          </limit>
          <dynamics>
            <spring_reference>0</spring_reference>
            <spring_stiffness>0</spring_stiffness>
          </dynamics>
          <use_parent_model_frame>1</use_parent_model_frame>
        </axis>
      </joint>
      <link name='arm2_link3'>
        <pose frame=''>0.9 1.2 1.12 1.5708 -0 1.5708</pose>
        <inertial>
          <pose frame=''>0.453976 0 0.000221 0 -0 0</pose>
          <mass>12.2232</mass>
          <inertia>
            <ixx>0.0258542</ixx>
            <ixy>-4.51893e-19</ixy>
            <ixz>-0.00120418</ixz>
            <iyy>0.983563</iyy>
            <iyz>-6.74155e-19</iyz>
            <izz>0.986967</izz>
          </inertia>
        </inertial>
        <collision name='arm2_link3_collision'>
          <pose frame=''>0 0 0 0 -0 0</pose>
          <geometry>
            <mesh>
              <scale>1 1 1</scale>
              <uri>/home/samleong/project_ws/src/grape_robot_description/meshes/arm2_link3.STL</uri>
            </mesh>
          </geometry>
          <surface>
            <contact>
              <ode/>
            </contact>
            <friction>
              <ode/>
              <torsional>
                <ode/>
              </torsional>
            </friction>
            <bounce/>
          </surface>
          <max_contacts>10</max_contacts>
        </collision>
        <visual name='arm2_link3_visual'>
          <pose frame=''>0 0 0 0 -0 0</pose>
          <geometry>
            <mesh>
              <scale>1 1 1</scale>
              <uri>/home/samleong/project_ws/src/grape_robot_description/meshes/arm2_link3.STL</uri>
            </mesh>
          </geometry>
          <material>
            <script>
              <name>Gazebo/OrangeTransparent</name>
              <uri>file://media/materials/scripts/gazebo.material</uri>
            </script>
          </material>
        </visual>
        <gravity>1</gravity>
        <velocity_decay/>
        <self_collide>0</self_collide>
        <kinematic>0</kinematic>
      </link>
      <joint name='arm2_joint3' type='revolute'>
        <child>arm2_link3</child>
        <parent>arm2_link2</parent>
        <axis>
          <xyz>-1 0 4e-06</xyz>
          <limit>
            <lower>-2.3</lower>
            <upper>2.3</upper>
            <effort>1000</effort>
            <velocity>10</velocity>
          </limit>
          <dynamics>
            <spring_reference>0</spring_reference>
            <spring_stiffness>0</spring_stiffness>
          </dynamics>
          <use_parent_model_frame>1</use_parent_model_frame>
        </axis>
      </joint>
      <link name='arm2_link4'>
        <pose frame=''>0.8225 2.1 1.12 1.5708 -0 1.5708</pose>
        <inertial>
          <pose frame=''>0 -0.003026 -0.038365 0 -0 0</pose>
          <mass>1.57382</mass>
          <inertia>
            <ixx>0.00391501</ixx>
            <ixy>3.33694e-20</ixy>
            <ixz>1.23177e-19</ixz>
            <iyy>0.00392884</iyy>
            <iyz>-5.54108e-05</iyz>
            <izz>0.00364961</izz>
          </inertia>
        </inertial>
        <collision name='arm2_link4_collision'>
          <pose frame=''>0 0 0 0 -0 0</pose>
          <geometry>
            <mesh>
              <scale>1 1 1</scale>
              <uri>/home/samleong/project_ws/src/grape_robot_description/meshes/arm2_link4.STL</uri>
            </mesh>
          </geometry>
          <surface>
            <contact>
              <ode/>
            </contact>
            <friction>
              <ode/>
              <torsional>
                <ode/>
              </torsional>
            </friction>
            <bounce/>
          </surface>
          <max_contacts>10</max_contacts>
        </collision>
        <visual name='arm2_link4_visual'>
          <pose frame=''>0 0 0 0 -0 0</pose>
          <geometry>
            <mesh>
              <scale>1 1 1</scale>
              <uri>/home/samleong/project_ws/src/grape_robot_description/meshes/arm2_link4.STL</uri>
            </mesh>
          </geometry>
          <material>
            <script>
              <name>Gazebo/OrangeTransparent</name>
              <uri>file://media/materials/scripts/gazebo.material</uri>
            </script>
          </material>
        </visual>
        <gravity>1</gravity>
        <velocity_decay/>
        <self_collide>0</self_collide>
        <kinematic>0</kinematic>
      </link>
      <joint name='arm2_joint4' type='revolute'>
        <child>arm2_link4</child>
        <parent>arm2_link3</parent>
        <axis>
          <xyz>-1 0 4e-06</xyz>
          <limit>
            <lower>-1.57</lower>
            <upper>1.57</upper>
            <effort>100</effort>
            <velocity>10</velocity>
          </limit>
          <dynamics>
            <spring_reference>0</spring_reference>
            <spring_stiffness>0</spring_stiffness>
          </dynamics>
          <use_parent_model_frame>1</use_parent_model_frame>
        </axis>
      </joint>
      <link name='arm2_link5'>
        <pose frame=''>0.7725 2.1 1.17 0 -0 1.5708</pose>
        <inertial>
          <pose frame=''>0.014461 4e-05 0.064147 0 -0 0</pose>
          <mass>1.25598</mass>
          <inertia>
            <ixx>0.00211286</ixx>
            <ixy>-3.60261e-06</ixy>
            <ixz>-0.000367368</ixz>
            <iyy>0.00329243</iyy>
            <iyz>-1.53504e-06</iyz>
            <izz>0.00267133</izz>
          </inertia>
        </inertial>
        <collision name='arm2_link5_collision'>
          <pose frame=''>0 0 0 0 -0 0</pose>
          <geometry>
            <mesh>
              <scale>1 1 1</scale>
              <uri>/home/samleong/project_ws/src/grape_robot_description/meshes/arm2_link5.STL</uri>
            </mesh>
          </geometry>
          <surface>
            <contact>
              <ode/>
            </contact>
            <friction>
              <ode/>
              <torsional>
                <ode/>
              </torsional>
            </friction>
            <bounce/>
          </surface>
          <max_contacts>10</max_contacts>
        </collision>
        <collision name='arm2_link5_fixed_joint_lump__arm2_end_effector_collision_1'>
          <pose frame=''>0.017042 0 0.075 -0.02537 0 0</pose>
          <geometry>
            <mesh>
              <scale>1 1 1</scale>
              <uri>/home/samleong/project_ws/src/grape_robot_description/meshes/arm2_end_effector.STL</uri>
            </mesh>
          </geometry>
          <surface>
            <contact>
              <ode/>
            </contact>
            <friction>
              <ode/>
              <torsional>
                <ode/>
              </torsional>
            </friction>
            <bounce/>
          </surface>
          <max_contacts>10</max_contacts>
        </collision>
        <collision name='arm2_link5_fixed_joint_lump__camera_collision_2'>
          <pose frame=''>0.087042 0.000507 0.094994 -0.02537 0 0</pose>
          <geometry>
            <box>
              <size>0.025 0.035 0.02</size>
            </box>
          </geometry>
          <surface>
            <contact>
              <ode/>
            </contact>
            <friction>
              <ode/>
              <torsional>
                <ode/>
              </torsional>
            </friction>
            <bounce/>
          </surface>
          <max_contacts>10</max_contacts>
        </collision>
        <visual name='arm2_link5_visual'>
          <pose frame=''>0 0 0 0 -0 0</pose>
          <geometry>
            <mesh>
              <scale>1 1 1</scale>
              <uri>/home/samleong/project_ws/src/grape_robot_description/meshes/arm2_link5.STL</uri>
            </mesh>
          </geometry>
          <material>
            <script>
              <name>Gazebo/Red</name>
              <uri>file://media/materials/scripts/gazebo.material</uri>
            </script>
          </material>
        </visual>
        <visual name='arm2_link5_fixed_joint_lump__arm2_end_effector_visual_1'>
          <pose frame=''>0.017042 0 0.075 -0.02537 0 0</pose>
          <geometry>
            <mesh>
              <scale>1 1 1</scale>
              <uri>/home/samleong/project_ws/src/grape_robot_description/meshes/arm2_end_effector.STL</uri>
            </mesh>
          </geometry>
          <material>
            <script>
              <name>Gazebo/Purple</name>
              <uri>file://media/materials/scripts/gazebo.material</uri>
            </script>
          </material>
        </visual>
        <visual name='arm2_link5_fixed_joint_lump__camera_visual_2'>
          <pose frame=''>0.087042 0.000507 0.094994 -0.02537 0 0</pose>
          <geometry>
            <box>
              <size>0.025 0.035 0.02</size>
            </box>
          </geometry>
          <material>
            <script>
              <name>Gazebo/Turquoise</name>
              <uri>file://media/materials/scripts/gazebo.material</uri>
            </script>
          </material>
        </visual>
        <velocity_decay/>
        <velocity_decay/>
        <gravity>1</gravity>
        <velocity_decay/>
        <sensor name='camera1' type='depth'>
          <update_rate>20</update_rate>
          <camera name='__default__'>
            <horizontal_fov>1.0472</horizontal_fov>
            <image>
              <width>640</width>
              <height>480</height>
              <format>R8G8B8</format>
            </image>
            <clip>
              <near>0.05</near>
              <far>3</far>
            </clip>
          </camera>
          <plugin name='camera_controller' filename='libgazebo_ros_openni_kinect.so'>
            <baseline>0.2</baseline>
            <alwaysOn>true</alwaysOn>
            <updateRate>1.0</updateRate>
            <cameraName>camera_ir</cameraName>
            <imageTopicName>/camera/color/image_raw</imageTopicName>
            <cameraInfoTopicName>/camera/color/camera_info</cameraInfoTopicName>
            <depthImageTopicName>/camera/depth/image_raw</depthImageTopicName>
            <depthImageInfoTopicName>/camera/depth/camera_info</depthImageInfoTopicName>
            <pointCloudTopicName>/camera/depth/points</pointCloudTopicName>
            <frameName>camera</frameName>
            <pointCloudCutoff>0.5</pointCloudCutoff>
            <pointCloudCutoffMax>3.0</pointCloudCutoffMax>
            <distortionK1>0.00000001</distortionK1>
            <distortionK2>0.00000001</distortionK2>
            <distortionK3>0.00000001</distortionK3>
            <distortionT1>0.00000001</distortionT1>
            <distortionT2>0.00000001</distortionT2>
            <CxPrime>0</CxPrime>
            <Cx>0</Cx>
            <Cy>0</Cy>
            <focalLength>0</focalLength>
            <hackBaseline>0</hackBaseline>
            <robotNamespace>/</robotNamespace>
          </plugin>
          <pose frame=''>0.087042 0.000507 0.094994 -0.02537 0 0</pose>
        </sensor>
        <self_collide>0</self_collide>
        <kinematic>0</kinematic>
      </link>
      <joint name='arm2_joint5' type='revolute'>
        <child>arm2_link5</child>
        <parent>arm2_link4</parent>
        <axis>
          <xyz>0 0 1</xyz>
          <limit>
            <lower>-1e+16</lower>
            <upper>1e+16</upper>
          </limit>
          <dynamics>
            <spring_reference>0</spring_reference>
            <spring_stiffness>0</spring_stiffness>
          </dynamics>
          <use_parent_model_frame>1</use_parent_model_frame>
        </axis>
      </joint>
      <link name='wheel_link1'>
        <pose frame=''>-1.0533 -0.45 0.294788 1.5708 -0 0</pose>
        <inertial>
          <pose frame=''>-0 0 0.15 0 -0 0</pose>
          <mass>61.8727</mass>
          <inertia>
            <ixx>1.47461</ixx>
            <ixy>1.80239e-15</ixy>
            <ixz>6.16205e-13</ixz>
            <iyy>1.47461</iyy>
            <iyz>-1.90858e-13</iyz>
            <izz>2.03315</izz>
          </inertia>
        </inertial>
        <collision name='wheel_link1_collision'>
          <pose frame=''>0 0 0 0 -0 0</pose>
          <geometry>
            <mesh>
              <scale>1 1 1</scale>
              <uri>/home/samleong/project_ws/src/grape_robot_description/meshes/wheel_link1.STL</uri>
            </mesh>
          </geometry>
          <surface>
            <contact>
              <ode>
                <kp>1e+07</kp>
                <kd>1</kd>
              </ode>
            </contact>
            <friction>
              <ode>
                <mu>1</mu>
                <mu2>1</mu2>
                <fdir1>1 0 0</fdir1>
              </ode>
              <torsional>
                <ode/>
              </torsional>
            </friction>
            <bounce/>
          </surface>
          <max_contacts>10</max_contacts>
        </collision>
        <visual name='wheel_link1_visual'>
          <pose frame=''>0 0 0 0 -0 0</pose>
          <geometry>
            <mesh>
              <scale>1 1 1</scale>
              <uri>/home/samleong/project_ws/src/grape_robot_description/meshes/wheel_link1.STL</uri>
            </mesh>
          </geometry>
          <material>
            <script>
              <name>Gazebo/Grey</name>
              <uri>file://media/materials/scripts/gazebo.material</uri>
            </script>
          </material>
        </visual>
        <gravity>1</gravity>
        <velocity_decay/>
        <self_collide>0</self_collide>
        <kinematic>0</kinematic>
      </link>
      <joint name='wheel_joint1' type='revolute'>
        <child>wheel_link1</child>
        <parent>base_footprint</parent>
        <axis>
          <xyz>0 -1 0</xyz>
          <limit>
            <lower>-1e+16</lower>
            <upper>1e+16</upper>
          </limit>
          <dynamics>
            <spring_reference>0</spring_reference>
            <spring_stiffness>0</spring_stiffness>
          </dynamics>
          <use_parent_model_frame>1</use_parent_model_frame>
        </axis>
      </joint>
      <link name='wheel_link2'>
        <pose frame=''>1.04974 -0.45 0.284193 1.5708 -0 0</pose>
        <inertial>
          <pose frame=''>-0 -0 0.15 0 -0 0</pose>
          <mass>61.8727</mass>
          <inertia>
            <ixx>1.47461</ixx>
            <ixy>-5.48166e-15</ixy>
            <ixz>4.05509e-13</ixz>
            <iyy>1.47461</iyy>
            <iyz>4.94238e-13</iyz>
            <izz>2.03315</izz>
          </inertia>
        </inertial>
        <collision name='wheel_link2_collision'>
          <pose frame=''>0 0 0 0 -0 0</pose>
          <geometry>
            <mesh>
              <scale>1 1 1</scale>
              <uri>/home/samleong/project_ws/src/grape_robot_description/meshes/wheel_link2.STL</uri>
            </mesh>
          </geometry>
          <surface>
            <contact>
              <ode>
                <kp>1e+07</kp>
                <kd>1</kd>
              </ode>
            </contact>
            <friction>
              <ode>
                <mu>1</mu>
                <mu2>1</mu2>
                <fdir1>1 0 0</fdir1>
              </ode>
              <torsional>
                <ode/>
              </torsional>
            </friction>
            <bounce/>
          </surface>
          <max_contacts>10</max_contacts>
        </collision>
        <visual name='wheel_link2_visual'>
          <pose frame=''>0 0 0 0 -0 0</pose>
          <geometry>
            <mesh>
              <scale>1 1 1</scale>
              <uri>/home/samleong/project_ws/src/grape_robot_description/meshes/wheel_link2.STL</uri>
            </mesh>
          </geometry>
          <material>
            <script>
              <name>Gazebo/Grey</name>
              <uri>file://media/materials/scripts/gazebo.material</uri>
            </script>
          </material>
        </visual>
        <gravity>1</gravity>
        <velocity_decay/>
        <self_collide>0</self_collide>
        <kinematic>0</kinematic>
      </link>
      <joint name='wheel_joint2' type='revolute'>
        <child>wheel_link2</child>
        <parent>base_footprint</parent>
        <axis>
          <xyz>0 -1 0</xyz>
          <limit>
            <lower>-1e+16</lower>
            <upper>1e+16</upper>
          </limit>
          <dynamics>
            <spring_reference>0</spring_reference>
            <spring_stiffness>0</spring_stiffness>
          </dynamics>
          <use_parent_model_frame>1</use_parent_model_frame>
        </axis>
      </joint>
      <link name='wheel_link3'>
        <pose frame=''>-1.05571 0.75 0.291085 1.5708 -0 3.14159</pose>
        <inertial>
          <pose frame=''>0 -0 -0.15 0 -0 0</pose>
          <mass>61.8727</mass>
          <inertia>
            <ixx>1.47461</ixx>
            <ixy>3.14011e-15</ixy>
            <ixz>4.06091e-13</ixz>
            <iyy>1.47461</iyy>
            <iyz>-4.94106e-13</iyz>
            <izz>2.03315</izz>
          </inertia>
        </inertial>
        <collision name='wheel_link3_collision'>
          <pose frame=''>0 0 0 0 -0 0</pose>
          <geometry>
            <mesh>
              <scale>1 1 1</scale>
              <uri>/home/samleong/project_ws/src/grape_robot_description/meshes/wheel_link3.STL</uri>
            </mesh>
          </geometry>
          <surface>
            <contact>
              <ode>
                <kp>1e+07</kp>
                <kd>1</kd>
              </ode>
            </contact>
            <friction>
              <ode>
                <mu>1</mu>
                <mu2>1</mu2>
                <fdir1>1 0 0</fdir1>
              </ode>
              <torsional>
                <ode/>
              </torsional>
            </friction>
            <bounce/>
          </surface>
          <max_contacts>10</max_contacts>
        </collision>
        <visual name='wheel_link3_visual'>
          <pose frame=''>0 0 0 0 -0 0</pose>
          <geometry>
            <mesh>
              <scale>1 1 1</scale>
              <uri>/home/samleong/project_ws/src/grape_robot_description/meshes/wheel_link3.STL</uri>
            </mesh>
          </geometry>
          <material>
            <script>
              <name>Gazebo/Grey</name>
              <uri>file://media/materials/scripts/gazebo.material</uri>
            </script>
          </material>
        </visual>
        <gravity>1</gravity>
        <velocity_decay/>
        <self_collide>0</self_collide>
        <kinematic>0</kinematic>
      </link>
      <joint name='wheel_joint3' type='revolute'>
        <child>wheel_link3</child>
        <parent>base_footprint</parent>
        <axis>
          <xyz>0 1 0</xyz>
          <limit>
            <lower>-1e+16</lower>
            <upper>1e+16</upper>
          </limit>
          <dynamics>
            <spring_reference>0</spring_reference>
            <spring_stiffness>0</spring_stiffness>
          </dynamics>
          <use_parent_model_frame>1</use_parent_model_frame>
        </axis>
      </joint>
      <link name='wheel_link4'>
        <pose frame=''>1.05 0.75 0.29 1.5708 -0 3.14159</pose>
        <inertial>
          <pose frame=''>0 -0 -0.15 0 -0 0</pose>
          <mass>61.8727</mass>
          <inertia>
            <ixx>1.47461</ixx>
            <ixy>6.62312e-15</ixy>
            <ixz>4.06269e-13</ixz>
            <iyy>1.47461</iyy>
            <iyz>-4.93807e-13</iyz>
            <izz>2.03315</izz>
          </inertia>
        </inertial>
        <collision name='wheel_link4_collision'>
          <pose frame=''>0 0 0 0 -0 0</pose>
          <geometry>
            <mesh>
              <scale>1 1 1</scale>
              <uri>/home/samleong/project_ws/src/grape_robot_description/meshes/wheel_link4.STL</uri>
            </mesh>
          </geometry>
          <surface>
            <contact>
              <ode>
                <kp>1e+07</kp>
                <kd>1</kd>
              </ode>
            </contact>
            <friction>
              <ode>
                <mu>1</mu>
                <mu2>1</mu2>
                <fdir1>1 0 0</fdir1>
              </ode>
              <torsional>
                <ode/>
              </torsional>
            </friction>
            <bounce/>
          </surface>
          <max_contacts>10</max_contacts>
        </collision>
        <visual name='wheel_link4_visual'>
          <pose frame=''>0 0 0 0 -0 0</pose>
          <geometry>
            <mesh>
              <scale>1 1 1</scale>
              <uri>/home/samleong/project_ws/src/grape_robot_description/meshes/wheel_link4.STL</uri>
            </mesh>
          </geometry>
          <material>
            <script>
              <name>Gazebo/Grey</name>
              <uri>file://media/materials/scripts/gazebo.material</uri>
            </script>
          </material>
        </visual>
        <gravity>1</gravity>
        <velocity_decay/>
        <self_collide>0</self_collide>
        <kinematic>0</kinematic>
      </link>
      <joint name='wheel_joint4' type='revolute'>
        <child>wheel_link4</child>
        <parent>base_footprint</parent>
        <axis>
          <xyz>0 -1 0</xyz>
          <limit>
            <lower>-1e+16</lower>
            <upper>1e+16</upper>
          </limit>
          <dynamics>
            <spring_reference>0</spring_reference>
            <spring_stiffness>0</spring_stiffness>
          </dynamics>
          <use_parent_model_frame>1</use_parent_model_frame>
        </axis>
      </joint>
      <plugin name='car_controller' filename='libgazebo_ros_planar_move.so'>
        <commandTopic>cmd_vel</commandTopic>
        <odometryTopic>odom</odometryTopic>
        <odometryFrame>odom</odometryFrame>
        <odometryRate>50.0</odometryRate>
        <robotBaseFrame>base_footprint</robotBaseFrame>
        <robotNamespace>/</robotNamespace>
      </plugin>
      <static>0</static>
      <plugin name='gazebo_ros_control' filename='libgazebo_ros_control.so'>
        <robotNamespace>/</robotNamespace>
        <legacyModeNS>true</legacyModeNS>
      </plugin>
      <pose frame=''>0 -3 0 0 -0 0</pose>
    </model>
    <model name='table'>
      <static>1</static>
      <link name='link'>
        <collision name='surface'>
          <pose frame=''>0 0 1 0 -0 0</pose>
          <geometry>
            <box>
              <size>1.5 0.8 0.03</size>
            </box>
          </geometry>
          <surface>
            <friction>
              <ode>
                <mu>0.6</mu>
                <mu2>0.6</mu2>
              </ode>
              <torsional>
                <ode/>
              </torsional>
            </friction>
            <contact>
              <ode/>
            </contact>
            <bounce/>
          </surface>
          <max_contacts>10</max_contacts>
        </collision>
        <visual name='visual1'>
          <pose frame=''>0 0 1 0 -0 0</pose>
          <geometry>
            <box>
              <size>1.5 0.8 0.03</size>
            </box>
          </geometry>
          <material>
            <script>
              <uri>file://media/materials/scripts/gazebo.material</uri>
              <name>Gazebo/Wood</name>
            </script>
          </material>
        </visual>
        <collision name='front_left_leg'>
          <pose frame=''>0.68 0.38 0.5 0 -0 0</pose>
          <geometry>
            <cylinder>
              <radius>0.02</radius>
              <length>1</length>
            </cylinder>
          </geometry>
          <max_contacts>10</max_contacts>
          <surface>
            <contact>
              <ode/>
            </contact>
            <bounce/>
            <friction>
              <torsional>
                <ode/>
              </torsional>
              <ode/>
            </friction>
          </surface>
        </collision>
        <visual name='front_left_leg'>
          <pose frame=''>0.68 0.38 0.5 0 -0 0</pose>
          <geometry>
            <cylinder>
              <radius>0.02</radius>
              <length>1</length>
            </cylinder>
          </geometry>
          <material>
            <script>
              <uri>file://media/materials/scripts/gazebo.material</uri>
              <name>Gazebo/Grey</name>
            </script>
          </material>
        </visual>
        <collision name='front_right_leg'>
          <pose frame=''>0.68 -0.38 0.5 0 -0 0</pose>
          <geometry>
            <cylinder>
              <radius>0.02</radius>
              <length>1</length>
            </cylinder>
          </geometry>
          <max_contacts>10</max_contacts>
          <surface>
            <contact>
              <ode/>
            </contact>
            <bounce/>
            <friction>
              <torsional>
                <ode/>
              </torsional>
              <ode/>
            </friction>
          </surface>
        </collision>
        <visual name='front_right_leg'>
          <pose frame=''>0.68 -0.38 0.5 0 -0 0</pose>
          <geometry>
            <cylinder>
              <radius>0.02</radius>
              <length>1</length>
            </cylinder>
          </geometry>
          <material>
            <script>
              <uri>file://media/materials/scripts/gazebo.material</uri>
              <name>Gazebo/Grey</name>
            </script>
          </material>
        </visual>
        <collision name='back_right_leg'>
          <pose frame=''>-0.68 -0.38 0.5 0 -0 0</pose>
          <geometry>
            <cylinder>
              <radius>0.02</radius>
              <length>1</length>
            </cylinder>
          </geometry>
          <max_contacts>10</max_contacts>
          <surface>
            <contact>
              <ode/>
            </contact>
            <bounce/>
            <friction>
              <torsional>
                <ode/>
              </torsional>
              <ode/>
            </friction>
          </surface>
        </collision>
        <visual name='back_right_leg'>
          <pose frame=''>-0.68 -0.38 0.5 0 -0 0</pose>
          <geometry>
            <cylinder>
              <radius>0.02</radius>
              <length>1</length>
            </cylinder>
          </geometry>
          <material>
            <script>
              <uri>file://media/materials/scripts/gazebo.material</uri>
              <name>Gazebo/Grey</name>
            </script>
          </material>
        </visual>
        <collision name='back_left_leg'>
          <pose frame=''>-0.68 0.38 0.5 0 -0 0</pose>
          <geometry>
            <cylinder>
              <radius>0.02</radius>
              <length>1</length>
            </cylinder>
          </geometry>
          <max_contacts>10</max_contacts>
          <surface>
            <contact>
              <ode/>
            </contact>
            <bounce/>
            <friction>
              <torsional>
                <ode/>
              </torsional>
              <ode/>
            </friction>
          </surface>
        </collision>
        <visual name='back_left_leg'>
          <pose frame=''>-0.68 0.38 0.5 0 -0 0</pose>
          <geometry>
            <cylinder>
              <radius>0.02</radius>
              <length>1</length>
            </cylinder>
          </geometry>
          <material>
            <script>
              <uri>file://media/materials/scripts/gazebo.material</uri>
              <name>Gazebo/Grey</name>
            </script>
          </material>
        </visual>
        <self_collide>0</self_collide>
        <kinematic>0</kinematic>
      </link>
      <pose frame=''>0.842422 0.342139 0 0 -0 0</pose>
    </model>
    <model name='grape'>
      <static>0</static>
      <link name='body'>
        <pose frame=''>0 0 0.2 0 -0 0</pose>
        <collision name='collision'>
          <geometry>
            <cylinder>
              <radius>0.05</radius>
              <length>0.4</length>
            </cylinder>
          </geometry>
          <max_contacts>10</max_contacts>
          <surface>
            <contact>
              <ode/>
            </contact>
            <bounce/>
            <friction>
              <torsional>
                <ode/>
              </torsional>
              <ode/>
            </friction>
          </surface>
        </collision>
        <visual name='visual'>
          <geometry>
            <mesh>
              <uri>/home/samleong/gazebo_models/grape/model.dae</uri>
              <scale>2 2 2</scale>
            </mesh>
          </geometry>
        </visual>
        <self_collide>0</self_collide>
        <inertial>
          <inertia>
            <ixx>1</ixx>
            <ixy>0</ixy>
            <ixz>0</ixz>
            <iyy>1</iyy>
            <iyz>0</iyz>
            <izz>1</izz>
          </inertia>
          <mass>1</mass>
        </inertial>
        <kinematic>0</kinematic>
      </link>
      <link name='vine'>
        <pose frame=''>0 0 0.5 0 -0 0</pose>
        <collision name='collision'>
          <geometry>
            <cylinder>
              <radius>0.005</radius>
              <length>0.2</length>
            </cylinder>
          </geometry>
          <max_contacts>10</max_contacts>
          <surface>
            <contact>
              <ode/>
            </contact>
            <bounce/>
            <friction>
              <torsional>
                <ode/>
              </torsional>
              <ode/>
            </friction>
          </surface>
        </collision>
        <visual name='visual'>
          <geometry>
            <cylinder>
              <radius>0.005</radius>
              <length>0.2</length>
            </cylinder>
          </geometry>
          <material>
            <ambient>0 0 0 1</ambient>
            <diffuse>1 1 0.3 1</diffuse>
            <specular>0 0 0 0</specular>
            <emissive>0 0 0 1</emissive>
          </material>
        </visual>
        <self_collide>0</self_collide>
        <inertial>
          <inertia>
            <ixx>1</ixx>
            <ixy>0</ixy>
            <ixz>0</ixz>
            <iyy>1</iyy>
            <iyz>0</iyz>
            <izz>1</izz>
          </inertia>
          <mass>1</mass>
        </inertial>
        <kinematic>0</kinematic>
      </link>
      <link name='head'>
        <pose frame=''>0 0 0.6 0 -0 0</pose>
        <collision name='collision'>
          <geometry>
            <cylinder>
              <radius>0.035</radius>
              <length>0.02</length>
            </cylinder>
          </geometry>
          <max_contacts>10</max_contacts>
          <surface>
            <contact>
              <ode/>
            </contact>
            <bounce/>
            <friction>
              <torsional>
                <ode/>
              </torsional>
              <ode/>
            </friction>
          </surface>
        </collision>
        <visual name='visual'>
          <geometry>
            <cylinder>
              <radius>0.035</radius>
              <length>0.02</length>
            </cylinder>
          </geometry>
          <material>
            <ambient>0 0 0 1</ambient>
            <diffuse>1 1 0.3 1</diffuse>
            <specular>0 0 0 0</specular>
            <emissive>0 0 0 1</emissive>
          </material>
        </visual>
        <self_collide>0</self_collide>
        <inertial>
          <inertia>
            <ixx>1</ixx>
            <ixy>0</ixy>
            <ixz>0</ixz>
            <iyy>1</iyy>
            <iyz>0</iyz>
            <izz>1</izz>
          </inertia>
          <mass>1</mass>
        </inertial>
        <kinematic>0</kinematic>
      </link>
      <joint name='vine_joint' type='fixed'>
        <pose frame=''>0 0 0.1 0 -0 0</pose>
        <child>vine</child>
        <parent>body</parent>
        <axis>
          <xyz>0 0 1</xyz>
          <use_parent_model_frame>0</use_parent_model_frame>
          <limit>
            <lower>-1e+16</lower>
            <upper>1e+16</upper>
          </limit>
        </axis>
      </joint>
      <joint name='head_joint' type='fixed'>
        <pose frame=''>0 0 0.03 0 -0 0</pose>
        <child>head</child>
        <parent>vine</parent>
        <axis>
          <xyz>0 0 1</xyz>
          <use_parent_model_frame>0</use_parent_model_frame>
          <limit>
            <lower>-1e+16</lower>
            <upper>1e+16</upper>
          </limit>
        </axis>
      </joint>
      <pose frame=''>1.01914 -0.04265 0 0 -0 0</pose>
    </model>
    <state world_name='default'>
      <sim_time>1041 322000000</sim_time>
      <real_time>236 735490373</real_time>
      <wall_time>1594120212 183152402</wall_time>
      <iterations>172332</iterations>
      <model name='grape'>
        <pose frame=''>0.697857 0.559039 1.01501 -3.4e-05 -0.000183 -2.22999</pose>
        <scale>1 1 1</scale>
        <link name='body'>
          <pose frame=''>0.697885 0.559064 1.21501 -3.4e-05 -0.000183 -2.22999</pose>
          <velocity>-0.001099 0.000756 -0.000247 -0.003542 -0.005307 -3.5e-05</velocity>
          <acceleration>-0.047419 0.059915 -9.79349 -0.061714 -0.048852 -0.000425</acceleration>
          <wrench>-0.047419 0.059915 -9.79349 0 -0 0</wrench>
        </link>
        <link name='head'>
          <pose frame=''>0.69794 0.559114 1.61501 -3.4e-05 -0.000183 -2.22999</pose>
          <velocity>-0.003193 0.002132 -0.00025 -0.003509 -0.005283 -3.5e-05</velocity>
          <acceleration>0.036098 -0.045608 -9.8059 0.04208 0.033311 0.000207</acceleration>
          <wrench>0.036098 -0.045608 -9.8059 0 -0 0</wrench>
        </link>
        <link name='vine'>
          <pose frame=''>0.697927 0.559101 1.51501 -3.4e-05 -0.000183 -2.22999</pose>
          <velocity>-0.00267 0.00179 -0.000249 -0.003523 -0.005293 -3.5e-05</velocity>
          <acceleration>0.011321 -0.014307 -9.80061 -0.002901 -0.002295 0.000223</acceleration>
          <wrench>0.011321 -0.014307 -9.80061 0 -0 0</wrench>
        </link>
      </model>
      <model name='grape_robot'>
        <pose frame=''>-5.6e-05 -3.00001 0.000521 -0.043322 -0.000514 8.9e-05</pose>
        <scale>1 1 1</scale>
        <link name='arm1_link1'>
          <pose frame=''>-0.40048 -2.96453 0.819545 -0.000558 0.043472 1.56985</pose>
          <velocity>5.8e-05 0.000198 1.8e-05 -0.006078 7.8e-05 4.7e-05</velocity>
          <acceleration>0.06826 1.04158 -0.018692 0.581056 0.084072 0.0501</acceleration>
          <wrench>1.00825 15.3849 -0.276087 0 -0 0</wrench>
        </link>
        <link name='arm1_link2'>
          <pose frame=''>-0.453135 -2.95147 1.11923 1.57024 0.043403 1.56985</pose>
          <velocity>7.9e-05 0.001188 -5.2e-05 0.003543 6.9e-05 5.7e-05</velocity>
          <acceleration>0.043033 1.28365 2.0677 0.199024 1.21724 0.005621</acceleration>
          <wrench>1.63911 48.8931 78.757 0 -0 0</wrench>
        </link>
        <link name='arm1_link3'>
          <pose frame=''>-0.3995 -1.75265 1.06719 1.57024 0.04347 1.56985</pose>
          <velocity>7e-06 0.001381 0.004164 0.003735 0.000103 5.5e-05</velocity>
          <acceleration>-0.028635 1.47801 6.40277 0.064602 0.129985 -0.219342</acceleration>
          <wrench>-0.455164 23.4933 101.773 0 -0 0</wrench>
        </link>
        <link name='arm1_link4'>
          <pose frame=''>-0.450866 -0.55374 1.01501 1.57023 0.043451 1.56985</pose>
          <velocity>-6.4e-05 0.001569 0.008553 0.004691 -2.6e-05 7.8e-05</velocity>
          <acceleration>-0.072327 1.59686 9.09414 -3.00348 -0.039018 0.074209</acceleration>
          <wrench>-0.189849 4.19156 23.871 0 -0 0</wrench>
        </link>
        <link name='arm2_link1'>
          <pose frame=''>0.89952 -2.96441 0.820212 -0.000465 0.043492 1.57205</pose>
          <velocity>5.9e-05 0.000759 -0.000105 -0.002378 6.7e-05 8.7e-05</velocity>
          <acceleration>0.068139 1.08896 -0.119833 -2.2306 0.072704 0.088609</acceleration>
          <wrench>1.00646 16.0847 -1.77002 0 -0 0</wrench>
        </link>
        <link name='arm2_link2'>
          <pose frame=''>0.846864 -2.95147 1.1199 1.57033 0.043412 1.57205</pose>
          <velocity>7.9e-05 0.001247 -0.000139 0.00758 7e-05 7.1e-05</velocity>
          <acceleration>0.034984 1.44791 4.40134 0.421995 1.21977 0.019081</acceleration>
          <wrench>1.33251 55.1498 167.644 0 -0 0</wrench>
        </link>
        <link name='arm2_link3'>
          <pose frame=''>0.897868 -1.75254 1.06785 1.57032 0.043438 1.57205</pose>
          <velocity>-9e-06 0.001646 0.008929 0.007794 -2.8e-05 7.6e-05</velocity>
          <acceleration>-0.043198 1.79946 12.4644 0.204081 -1.1528 0.115146</acceleration>
          <wrench>-0.528022 21.9952 152.355 0 -0 0</wrench>
        </link>
        <link name='arm2_link4'>
          <pose frame=''>0.819245 -0.853487 1.02873 1.57032 0.043472 1.57205</pose>
          <velocity>-7.6e-05 0.001944 0.01593 0.006156 2.3e-05 6.5e-05</velocity>
          <acceleration>-0.075995 1.96067 15.9295 0.323137 0.026973 0.153268</acceleration>
          <wrench>-0.119602 3.08575 25.0702 0 -0 0</wrench>
        </link>
        <link name='arm2_link5'>
          <pose frame=''>0.769219 -0.851378 1.07866 -0.000478 0.043467 1.57201</pose>
          <velocity>-7.1e-05 0.00163 0.015947 0.00618 6e-06 6.2e-05</velocity>
          <acceleration>-0.071983 1.23823 16.0539 -2.32327 -0.142164 -0.799588</acceleration>
          <wrench>-0.090409 1.55519 20.1634 0 -0 0</wrench>
        </link>
        <link name='base_footprint'>
          <pose frame=''>-5.6e-05 -3.00001 0.000521 -0.043322 -0.000514 8.9e-05</pose>
          <velocity>0 1e-06 -3e-06 -0.001089 7.4e-05 2e-06</velocity>
          <acceleration>0.043044 0.637025 -0.029313 -1.08879 0.074364 0.001453</acceleration>
          <wrench>84.7156 1253.74 -57.6922 0 -0 0</wrench>
        </link>
        <link name='grip_leftlink'>
          <pose frame=''>-0.448203 -0.37326 1.02218 -3.09815 0.00057 3.14058</pose>
          <velocity>-8.1e-05 0.001522 0.009392 0.004991 -0.000234 7.4e-05</velocity>
          <acceleration>-0.078183 1.59551 9.44788 2.4438 1.33786 -2.92571</acceleration>
          <wrench>-0.015491 0.316134 1.872 0 -0 0</wrench>
        </link>
        <link name='grip_rightlink'>
          <pose frame=''>-0.348188 -0.374656 0.992266 -0.043439 -0.000552 -0.000839</pose>
          <velocity>-7.8e-05 0.001679 0.009369 0.005089 0.00016 8.7e-05</velocity>
          <acceleration>-0.07662 1.61159 9.43684 -1.19101 0.156244 0.038465</acceleration>
          <wrench>-0.015181 0.31932 1.86982 0 -0 0</wrench>
        </link>
        <link name='wheel_link1'>
          <pose frame=''>-1.05348 -3.43691 0.31398 1.52748 -0.000304 8e-05</pose>
          <velocity>2.4e-05 0.000339 0.00055 -0.001089 7.4e-05 2e-06</velocity>
          <acceleration>0.02504 0.346561 0.713666 -1.08909 0.053661 0.003994</acceleration>
          <wrench>1.54929 21.4427 44.1564 0 -0 0</wrench>
        </link>
        <link name='wheel_link2'>
          <pose frame=''>1.04957 -3.43718 0.304475 1.52748 0.000157 6e-05</pose>
          <velocity>2.4e-05 0.000334 0.000396 -0.001089 7.4e-05 2e-06</velocity>
          <acceleration>0.024336 0.341034 0.559079 -1.08903 0.053966 0.00398</acceleration>
          <wrench>1.50574 21.1007 34.5917 0 -0 0</wrench>
        </link>
        <link name='wheel_link3'>
          <pose frame=''>-1.05597 -2.2382 0.25831 1.61411 0.000709 -3.1415</pose>
          <velocity>1.8e-05 0.00028 -0.000755 -0.001082 6.9e-05 -1e-06</velocity>
          <acceleration>0.018685 0.286549 -0.592934 -1.08197 0.050088 -0.000557</acceleration>
          <wrench>1.1561 17.7295 -36.6864 0 -0 0</wrench>
        </link>
        <link name='wheel_link4'>
          <pose frame=''>1.04974 -2.23806 0.258308 1.61411 0.000715 -3.1415</pose>
          <velocity>1.8e-05 0.000283 -0.00091 -0.001096 6.9e-05 -2e-06</velocity>
          <acceleration>0.018622 0.290201 -0.746242 -1.09574 0.049795 -0.001509</acceleration>
          <wrench>1.15222 17.9555 -46.172 0 -0 0</wrench>
        </link>
      </model>
      <model name='ground_plane'>
        <pose frame=''>0 0 0 0 -0 0</pose>
        <scale>1 1 1</scale>
        <link name='link'>
          <pose frame=''>0 0 0 0 -0 0</pose>
          <velocity>0 0 0 0 -0 0</velocity>
          <acceleration>0 0 0 0 -0 0</acceleration>
          <wrench>0 0 0 0 -0 0</wrench>
        </link>
      </model>
      <model name='table'>
        <pose frame=''>0.602678 0.711311 0 0 -0 0</pose>
        <scale>1 1 1</scale>
        <link name='link'>
          <pose frame=''>0.602678 0.711311 0 0 -0 0</pose>
          <velocity>0 0 0 0 -0 0</velocity>
          <acceleration>0 0 0 0 -0 0</acceleration>
          <wrench>0 0 0 0 -0 0</wrench>
        </link>
      </model>
      <light name='sun'>
        <pose frame=''>0 0 10 0 -0 0</pose>
      </light>
    </state>
    <gui fullscreen='0'>
      <camera name='user_camera'>
        <pose frame=''>4.15705 3.08676 3.00689 0 0.207642 -2.64699</pose>
        <view_controller>orbit</view_controller>
        <projection_type>perspective</projection_type>
      </camera>
    </gui>
  </world>
</sdf>
