<?xml version="1.0" encoding="utf-8"?>
<!-- This URDF was automatically created by SolidWorks to URDF Exporter! Originally created by Stephen Brawner (brawner@gmail.com) 
     Commit Version: 1.5.1-0-g916b5db  Build Version: 1.5.7152.31018
     For more information, please see http://wiki.ros.org/sw_urdf_exporter -->
<robot name="grape_robot" xmlns:xacro="http://www.ros.org/wiki/xacro">

  <xacro:property name="cameraLength" value="0.025"/>
  <xacro:property name="cameraWidth" value="0.035"/>
  <xacro:property name="cameraHeight" value="0.02"/>
  <xacro:property name="cameraMass" value="0.1"/>

<!-- Include more gazebo plugin into this file -->
 <xacro:include filename="$(find grape_robot_description)/urdf/grape_robot.gazebo" />

<!-- root link, on the ground just below the model origin -->
  <link name="base_footprint">
   <visual>
      <origin xyz="0 0 0" rpy="0 0 0" />
      <geometry>
        <box size="0.001 0.001 0.001" />
      </geometry>
    </visual>
   <collision>
      <origin xyz="0 0 0" rpy="0 0 0" />
      <geometry>
        <box size="0.001 0.001 0.001" />
      </geometry>
    </collision>
  </link>

  <joint name="base_link_joint" type="fixed">
    <origin xyz="0.0 0 0.30" rpy="0 0 0" />
    <parent link="base_footprint"/>
    <child link="car_base_link" />
  </joint>

<!--car_base-->
  <link
    name="car_base_link">
    <inertial>
      <origin
        xyz="0.00580731393949363 0 0.270806051655572"
        rpy="0 0 0" />
      <mass
        value="1894.1631388638" />
      <inertia
        ixx="396.671761506115"
        ixy="6.63296606534545E-15"
        ixz="-2.24613343178872"
        iyy="1331.09215138841"
        iyz="3.18624780731297E-15"
        izz="1654.47156695622" />
    </inertial>
    <visual>
      <origin
        xyz="0 0 0"
        rpy="0 0 0" />
      <geometry>
        <mesh
          filename="package://grape_robot_description/meshes/car_base_link.STL" />
      </geometry>
      <material
        name="">
        <color
          rgba="0 0 1 1" />
      </material>
    </visual>
    <collision>
      <origin
        xyz="0 0 0"
        rpy="0 0 0" />
      <geometry>
        <mesh
          filename="package://grape_robot_description/meshes/car_base_link.STL" />
      </geometry>
    </collision>
  </link>

  <joint name="hokuyo_joint" type="fixed">
    <axis xyz="0 1 0" />
    <origin xyz="1.45 0 .53" rpy="0 0 0"/>
    <parent link="car_base_link"/>
    <child link="hokuyo"/>
  </joint>

  <!-- Hokuyo Laser -->
  <link name="hokuyo">
    <collision>
      <origin xyz="0 0 0" rpy="0 0 0"/>
      <geometry>
    <box size="0.1 0.1 0.1"/>
      </geometry>
    </collision>

    <visual>
      <origin xyz="0 0 0" rpy="0 0 0"/>
      <geometry>
        <mesh filename="package://grape_robot_description/meshes/hokuyo.dae"/>
      </geometry>
    </visual>

    <inertial>
      <mass value="1e-5" />
      <origin xyz="0 0 0" rpy="0 0 0"/>
      <inertia ixx="1e-6" ixy="0" ixz="0" iyy="1e-6" iyz="0" izz="1e-6" />
    </inertial>
  </link>

<!--wheel_1-->
  <link
    name="wheel_link1">
    <inertial>
      <origin
        xyz="-7.61252172409854E-13 7.92699239582362E-13 0.149999999887995"
        rpy="0 0 0" />
      <mass
        value="61.8726812758105" />
      <inertia
        ixx="1.47461451392567"
        ixy="1.80238809085456E-15"
        ixz="6.16205092686963E-13"
        iyy="1.47461451392568"
        iyz="-1.90858121087764E-13"
        izz="2.03314801318378" />
    </inertial>
    <visual>
      <origin
        xyz="0 0 0"
        rpy="0 0 0" />
      <geometry>
        <mesh
          filename="package://grape_robot_description/meshes/wheel_link1.STL" />
      </geometry>
      <material
        name="">
        <color
          rgba="0.501960784313725 0.501960784313725 0.501960784313725 1" />
      </material>
    </visual>
    <collision>
      <origin
        xyz="0 0 0"
        rpy="0 0 0" />
      <geometry>
        <mesh
          filename="package://grape_robot_description/meshes/wheel_link1.STL" />
      </geometry>
    </collision>
  </link>
  <joint
    name="wheel_joint1"
    type="continuous">
    <origin
      xyz="-1.05329616030303 -0.45 -0.00521228742180946"
      rpy="1.5707963267949 0 0" />
    <parent
      link="car_base_link" />
    <child
      link="wheel_link1" />
    <axis
      xyz="0 0 1" />
  </joint>

<!--wheel_2-->
  <link
    name="wheel_link2">
    <inertial>
      <origin
        xyz="-1.01429975529754E-12 -4.03899136358632E-13 0.149999999887996"
        rpy="0 0 0" />
      <mass
        value="61.8726812758106" />
      <inertia
        ixx="1.47461451392568"
        ixy="-5.48165767698838E-15"
        ixz="4.05508967434282E-13"
        iyy="1.47461451392568"
        iyz="4.94238018773669E-13"
        izz="2.03314801318379" />
    </inertial>
    <visual>
      <origin
        xyz="0 0 0"
        rpy="0 0 0" />
      <geometry>
        <mesh
          filename="package://grape_robot_description/meshes/wheel_link2.STL" />
      </geometry>
      <material
        name="">
        <color
          rgba="0.501960784313725 0.501960784313725 0.501960784313725 1" />
      </material>
    </visual>
    <collision>
      <origin
        xyz="0 0 0"
        rpy="0 0 0" />
      <geometry>
        <mesh
          filename="package://grape_robot_description/meshes/wheel_link2.STL" />
      </geometry>
    </collision>
  </link>
  <joint
    name="wheel_joint2"
    type="continuous">
    <origin
      xyz="1.04973884255006 -0.45 -0.0158067771836876"
      rpy="1.5707963267949 0 0" />
    <parent
      link="car_base_link" />
    <child
      link="wheel_link2" />
    <axis
      xyz="0 0 1" />
  </joint>

<!--wheel_3-->
  <link
    name="wheel_link3">
    <inertial>
      <origin
        xyz="1.01456343326589E-12 -4.04121180963557E-13 -0.149999999887996"
        rpy="0 0 0" />
      <mass
        value="61.8726812758105" />
      <inertia
        ixx="1.47461451392567"
        ixy="3.14011460704025E-15"
        ixz="4.06091013784824E-13"
        iyy="1.47461451392567"
        iyz="-4.94105607703688E-13"
        izz="2.03314801318378" />
    </inertial>
    <visual>
      <origin
        xyz="0 0 0"
        rpy="0 0 0" />
      <geometry>
        <mesh
          filename="package://grape_robot_description/meshes/wheel_link3.STL" />
      </geometry>
      <material
        name="">
        <color
          rgba="0.501960784313725 0.501960784313725 0.501960784313725 1" />
      </material>
    </visual>
    <collision>
      <origin
        xyz="0 0 0"
        rpy="0 0 0" />
      <geometry>
        <mesh
          filename="package://grape_robot_description/meshes/wheel_link3.STL" />
      </geometry>
    </collision>
  </link>
  <joint
    name="wheel_joint3"
    type="continuous">
    <origin
      xyz="-1.05571050598439 0.75 -0.00891511020055424"
      rpy="1.5707963267949 0 3.14159265358979" />
    <parent
      link="car_base_link" />
    <child
      link="wheel_link3" />
    <axis
      xyz="0 0 1" />
  </joint>

<!--wheel_4-->
  <link
    name="wheel_link4">
    <inertial>
      <origin
        xyz="1.01474384450739E-12 -4.04343225568482E-13 -0.149999999887996"
        rpy="0 0 0" />
      <mass
        value="61.8726812758105" />
      <inertia
        ixx="1.47461451392568"
        ixy="6.62312380552213E-15"
        ixz="4.06269438403909E-13"
        iyy="1.47461451392567"
        iyz="-4.93806660334351E-13"
        izz="2.03314801318378" />
    </inertial>
    <visual>
      <origin
        xyz="0 0 0"
        rpy="0 0 0" />
      <geometry>
        <mesh
          filename="package://grape_robot_description/meshes/wheel_link4.STL" />
      </geometry>
      <material
        name="">
        <color
          rgba="0.501960784313725 0.501960784313725 0.501960784313725 1" />
      </material>
    </visual>
    <collision>
      <origin
        xyz="0 0 0"
        rpy="0 0 0" />
      <geometry>
        <mesh
          filename="package://grape_robot_description/meshes/wheel_link4.STL" />
      </geometry>
    </collision>
  </link>
  <joint
    name="wheel_joint4"
    type="continuous">
    <origin
      xyz="1.05 0.75 -0.01"
      rpy="1.5707963267949 0 3.14159265358979" />
    <parent
      link="car_base_link" />
    <child
      link="wheel_link4" />
    <axis
      xyz="0 0 -1" />
  </joint>

<!--basket-->
  <link
    name="basket_link">
    <inertial>
      <origin
        xyz="2.77555756156289E-17 0 0.305781840792512"
        rpy="0 0 0" />
      <mass
        value="45.3934969327129" />
      <inertia
        ixx="3.74116884013512"
        ixy="-3.98622473092369E-17"
        ixz="-2.26774385659417E-15"
        iyy="3.74116884013513"
        iyz="2.6559555243994E-15"
        izz="3.11198640550683" />
    </inertial>
    <visual>
      <origin
        xyz="0 0 0"
        rpy="0 0 0" />
      <geometry>
        <mesh
          filename="package://grape_robot_description/meshes/basket_link.STL" />
      </geometry>
      <material
        name="">
        <color
          rgba="0.909803921568627 0.443137254901961 0.0313725490196078 1" />
      </material>
    </visual>
    <collision>
      <origin
        xyz="0 0 0"
        rpy="0 0 0" />
      <geometry>
        <mesh
          filename="package://grape_robot_description/meshes/basket_link.STL" />
      </geometry>
    </collision>
  </link>
  <joint
    name="basket_joint"
    type="fixed">
    <origin
      xyz="-1.2 0 0.45"
      rpy="0 0 0" />
    <parent
      link="car_base_link" />
    <child
      link="basket_link" />
    <axis
      xyz="0 0 0" />
  </joint>

<!--arm1_base-->
  <link
    name="arm1_base_link">
    <inertial>
      <origin
        xyz="0 2.22044604925031E-16 0.0457907228954795"
        rpy="0 0 0" />
      <mass
        value="14.2823342166498" />
      <inertia
        ixx="0.216354531828994"
        ixy="2.40548322002118E-17"
        ixz="-2.90918589182568E-18"
        iyy="0.216354531828995"
        iyz="-9.31361402378746E-18"
        izz="0.411014437215888" />
    </inertial>
    <visual>
      <origin
        xyz="0 0 0"
        rpy="0 0 0" />
      <geometry>
        <mesh
          filename="package://grape_robot_description/meshes/arm1_base_link.STL" />
      </geometry>
      <material
        name="">
        <color
          rgba="0 1 0 1" />
      </material>
    </visual>
    <collision>
      <origin
        xyz="0 0 0"
        rpy="0 0 0" />
      <geometry>
        <mesh
          filename="package://grape_robot_description/meshes/arm1_base_link.STL" />
      </geometry>
    </collision>
  </link>
  <joint
    name="arm1_base_joint"
    type="fixed">
    <origin
      xyz="-0.4 0 0.45"
      rpy="0 0 1.5708" />
    <parent
      link="car_base_link" />
    <child
      link="arm1_base_link" />
    <axis
      xyz="0 0 0" />
  </joint>


<!--arm1_link1-->
  <link
    name="arm1_link1">
    <inertial>
      <origin
        xyz="0 1.11022302462516E-16 0.138894448505082"
        rpy="0 0 0" />
      <mass
        value="14.7706616501683" />
      <inertia
        ixx="0.176855530860697"
        ixy="7.73150498430043E-19"
        ixz="1.98597238115063E-18"
        iyy="0.18851302774814"
        iyz="0"
        izz="0.122105378162113" />
    </inertial>
    <visual>
      <origin
        xyz="0 0 0"
        rpy="0 0 0" />
      <geometry>
        <mesh
          filename="package://grape_robot_description/meshes/arm1_link1.STL" />
      </geometry>
      <material
        name="">
        <color
          rgba="0 1 0 1" />
      </material>
    </visual>
    <collision>
      <origin
        xyz="0 0 0"
        rpy="0 0 0" />
      <geometry>
        <mesh
          filename="package://grape_robot_description/meshes/arm1_link1.STL" />
      </geometry>
    </collision>
  </link>
  <joint
    name="arm1_joint1"
    type="continuous">
    <origin
      xyz="0 0 0.07"
      rpy="0 0 0" />
    <parent
      link="arm1_base_link" />
    <child
      link="arm1_link1" />
    <axis
      xyz="0 0 1" />
  </joint>

<!--arm1_link2-->
  <link
    name="arm1_link2">
    <inertial>
      <origin
        xyz="0.6 4.44089209850063E-16 0.0525000000000002"
        rpy="0 0 0" />
      <mass
        value="38.0892038860768" />
      <inertia
        ixx="0.248336311424493"
        ixy="5.96437573198553E-19"
        ixz="-4.74237699760504E-16"
        iyy="4.55187605424207"
        iyz="-1.64179883049194E-17"
        izz="4.44527028775544" />
    </inertial>
    <visual>
      <origin
        xyz="0 0 0"
        rpy="0 0 0" />
      <geometry>
        <mesh
          filename="package://grape_robot_description/meshes/arm1_link2.STL" />
      </geometry>
      <material
        name="">
        <color
          rgba="0 1 0 1" />
      </material>
    </visual>
    <collision>
      <origin
        xyz="0 0 0"
        rpy="0 0 0" />
      <geometry>
        <mesh
          filename="package://grape_robot_description/meshes/arm1_link2.STL" />
      </geometry>
    </collision>
  </link>
  <joint
    name="arm1_joint2"
    type="revolute">
    <origin
      xyz="0 0.0525 0.3"
      rpy="1.5708 0 0" />
    <parent
      link="arm1_link1" />
    <child
      link="arm1_link2" />
    <axis
      xyz="0 0 -1" />
    <limit
      lower="-3.14"
      upper="0"
      effort="1000"
      velocity="10" />
  </joint>

<!--arm1_link3-->
  <link
    name="arm1_link3">
    <inertial>
      <origin
        xyz="0.6 0 1.11022302462516E-16"
        rpy="0 0 0" />
      <mass
        value="15.8951879872733" />
      <inertia
        ixx="0.0337520465909674"
        ixy="1.13291705316171E-16"
        ixz="-1.34293601856446E-17"
        iyy="2.14536372200935"
        iyz="1.54652679551498E-18"
        izz="2.14990836067371" />
    </inertial>
    <visual>
      <origin
        xyz="0 0 0"
        rpy="0 0 0" />
      <geometry>
        <mesh
          filename="package://grape_robot_description/meshes/arm1_link3.STL" />
      </geometry>
      <material
        name="">
        <color
          rgba="0 1 0 1" />
      </material>
    </visual>
    <collision>
      <origin
        xyz="0 0 0"
        rpy="0 0 0" />
      <geometry>
        <mesh
          filename="package://grape_robot_description/meshes/arm1_link3.STL" />
      </geometry>
    </collision>
  </link>
  <joint
    name="arm1_joint3"
    type="revolute">
    <origin
      xyz="1.2 0 0.0525"
      rpy="0 0 0" />
    <parent
      link="arm1_link2" />
    <child
      link="arm1_link3" />
    <axis
      xyz="0 0 -1" />
    <limit
      lower="-2.4"
      upper="2.4"
      effort="1000"
      velocity="10" />
  </joint>

<!--arm1_link4-->
  <link
    name="arm1_link4">
    <inertial>
      <origin
        xyz="0.115301967346706 2.02233545465447E-08 0.0525002979419241"
        rpy="0 0 0" />
      <mass
        value="2.62487870953122" />
      <inertia
        ixx="0.00962569495785021"
        ixy="2.90721133866813E-09"
        ixz="7.23028280392494E-08"
        iyy="0.0145548797169527"
        iyz="2.14764883190223E-08"
        izz="0.0137689400344086" />
    </inertial>
    <visual>
      <origin
        xyz="0 0 0"
        rpy="0 0 0" />
      <geometry>
        <mesh
          filename="package://grape_robot_description/meshes/arm1_link4.STL" />
      </geometry>
      <material
        name="">
        <color
          rgba="0 1 1 1" />
      </material>
    </visual>
    <collision>
      <origin
        xyz="0 0 0"
        rpy="0 0 0" />
      <geometry>
        <mesh
          filename="package://grape_robot_description/meshes/arm1_link4.STL" />
      </geometry>
    </collision>
  </link>
  <joint
    name="arm1_joint4"
    type="revolute">
    <origin
      xyz="1.2 0 -0.0525"
      rpy="0 0 0" />
    <parent
      link="arm1_link3" />
    <child
      link="arm1_link4" />
    <axis
      xyz="0 0 -1" />
    <limit
      lower="-1.57"
      upper="1.57"
      effort="100"
      velocity="10" />
  </joint>

<!--gripper_rightlink-->
  <link
    name="grip_rightlink">
    <inertial>
      <origin
        xyz="0.0666195620143888 0.0148545913482053 0.0150000000000001"
        rpy="0 0 0" />
      <mass
        value="0.198139867656488" />
      <inertia
        ixx="7.83981468618559E-05"
        ixy="-0.000114503714158253"
        ixz="6.83773264492249E-21"
        iyy="0.000455719454816792"
        iyz="-2.22152606157124E-21"
        izz="0.000504396621530175" />
    </inertial>
    <visual>
      <origin
        xyz="0 0 0"
        rpy="0 0 0" />
      <geometry>
        <mesh
          filename="package://grape_robot_description/meshes/grip_rightlink.STL" />
      </geometry>
      <material
        name="">
        <color
          rgba="1 0 0 1" />
      </material>
    </visual>
    <collision>
      <origin
        xyz="0 0 0"
        rpy="0 0 0" />
      <geometry>
        <mesh
          filename="package://grape_robot_description/meshes/grip_rightlink.STL" />
      </geometry>
    </collision>
  </link>
  <joint
    name="grip_rightjoint"
    type="revolute">
    <origin
      xyz="0.18 -0.015 0.1025"
      rpy="-1.5708 -1.5708 0" />
    <parent
      link="arm1_link4" />
    <child
      link="grip_rightlink" />
    <axis
      xyz="0 0 -1" />
    <limit
      lower="-1.57"
      upper="0"
      effort="50"
      velocity="10" />
  </joint>

<!--gripper_leftlink-->
  <link
    name="grip_leftlink">
    <inertial>
      <origin
        xyz="0.0666195620143888 0.0148545913482053 0.0150000000000001"
        rpy="0 0 0" />
      <mass
        value="0.198139867656487" />
      <inertia
        ixx="7.83981468618554E-05"
        ixy="-0.000114503714158252"
        ixz="-1.41742767481516E-20"
        iyy="0.000455719454816791"
        iyz="-8.68894851087599E-21"
        izz="0.000504396621530174" />
    </inertial>
    <visual>
      <origin
        xyz="0 0 0"
        rpy="0 0 0" />
      <geometry>
        <mesh
          filename="package://grape_robot_description/meshes/grip_leftlink.STL" />
      </geometry>
      <material
        name="">
        <color
          rgba="1 0 0 1" />
      </material>
    </visual>
    <collision>
      <origin
        xyz="0 0 0"
        rpy="0 0 0" />
      <geometry>
        <mesh
          filename="package://grape_robot_description/meshes/grip_leftlink.STL" />
      </geometry>
    </collision>
  </link>
  <joint
    name="grip_leftjoint"
    type="revolute">
    <origin
      xyz="0.18 0.015 0.0025"
      rpy="1.5708 1.5708 0" />
    <parent
      link="arm1_link4" />
    <child
      link="grip_leftlink" />
    <axis
      xyz="0 0 1" />
    <limit
      lower="0"
      upper="1.57"
      effort="50"
      velocity="10" />
  </joint>

<!--arm2_base-->
  <link
    name="arm2_base_link">
    <inertial>
      <origin
        xyz="0 2.22044604925031E-16 0.0457907228954795"
        rpy="0 0 0" />
      <mass
        value="14.2823342166498" />
      <inertia
        ixx="0.216354531828994"
        ixy="-2.2204460492503E-17"
        ixz="2.87322569476366E-18"
        iyy="0.216354531828995"
        iyz="-1.40875859477192E-17"
        izz="0.411014437215888" />
    </inertial>
    <visual>
      <origin
        xyz="0 0 0"
        rpy="0 0 0" />
      <geometry>
        <mesh
          filename="package://grape_robot_description/meshes/arm2_base_link.STL" />
      </geometry>
      <material
        name="">
        <color
          rgba="1 0.501960784313725 0.501960784313725 1" />
      </material>
    </visual>
    <collision>
      <origin
        xyz="0 0 0"
        rpy="0 0 0" />
      <geometry>
        <mesh
          filename="package://grape_robot_description/meshes/arm2_base_link.STL" />
      </geometry>
    </collision>
  </link>
  <joint
    name="arm2_base_joint"
    type="fixed">
    <origin
      xyz="0.9 0 0.45"
      rpy="0 0 1.5707963267949" />
    <parent
      link="car_base_link" />
    <child
      link="arm2_base_link" />
    <axis
      xyz="0 0 0" />
  </joint>

<!--arm2_link1-->
  <link
    name="arm2_link1">
    <inertial>
      <origin
        xyz="0 0 0.138894448505083"
        rpy="0 0 0" />
      <mass
        value="14.7706616501684" />
      <inertia
        ixx="0.176855530860697"
        ixy="7.73150498430043E-19"
        ixz="2.53181922155772E-18"
        iyy="0.18851302774814"
        iyz="-2.11758236813575E-19"
        izz="0.122105378162113" />
    </inertial>
    <visual>
      <origin
        xyz="0 0 0"
        rpy="0 0 0" />
      <geometry>
        <mesh
          filename="package://grape_robot_description/meshes/arm2_link1.STL" />
      </geometry>
      <material
        name="">
        <color
          rgba="1 0.501960784313725 0.501960784313725 1" />
      </material>
    </visual>
    <collision>
      <origin
        xyz="0 0 0"
        rpy="0 0 0" />
      <geometry>
        <mesh
          filename="package://grape_robot_description/meshes/arm2_link1.STL" />
      </geometry>
    </collision>
  </link>
  <joint
    name="arm2_joint1"
    type="continuous">
    <origin
      xyz="0 0 0.0700000000000001"
      rpy="0 0 0" />
    <parent
      link="arm2_base_link" />
    <child
      link="arm2_link1" />
    <axis
      xyz="0 0 1" />
  </joint>

<!--arm2_link2-->
  <link
    name="arm2_link2">
    <inertial>
      <origin
        xyz="0.600000000000001 0 0.0525"
        rpy="0 0 0" />
      <mass
        value="38.0892038860768" />
      <inertia
        ixx="0.248336311424493"
        ixy="2.40837968482128E-17"
        ixz="-8.23093288397068E-16"
        iyy="4.55187605424208"
        iyz="-1.01048526814981E-17"
        izz="4.44527028775545" />
    </inertial>
    <visual>
      <origin
        xyz="0 0 0"
        rpy="0 0 0" />
      <geometry>
        <mesh
          filename="package://grape_robot_description/meshes/arm2_link2.STL" />
      </geometry>
      <material
        name="">
        <color
          rgba="1 0.501960784313725 0.501960784313725 1" />
      </material>
    </visual>
    <collision>
      <origin
        xyz="0 0 0"
        rpy="0 0 0" />
      <geometry>
        <mesh
          filename="package://grape_robot_description/meshes/arm2_link2.STL" />
      </geometry>
    </collision>
  </link>
  <joint
    name="arm2_joint2"
    type="revolute">
    <origin
      xyz="0 0.0525 0.3"
      rpy="1.5708 0 0" />
    <parent
      link="arm2_link1" />
    <child
      link="arm2_link2" />
    <axis
      xyz="0 0 -1" />
    <limit
      lower="-3.14"
      upper="0"
      effort="1000"
      velocity="10" />
  </joint>

<!--arm2_link3-->
  <link
    name="arm2_link3">
    <inertial>
      <origin
        xyz="0.453975766570315 0 0.000220875920573071"
        rpy="0 0 0" />
      <mass
        value="12.2231802347404" />
      <inertia
        ixx="0.0258541672578399"
        ixy="-4.51892981620503E-19"
        ixz="-0.0012041789848222"
        iyy="0.983562956407477"
        iyz="-6.74155057561443E-19"
        izz="0.986967221982291" />
    </inertial>
    <visual>
      <origin
        xyz="0 0 0"
        rpy="0 0 0" />
      <geometry>
        <mesh
          filename="package://grape_robot_description/meshes/arm2_link3.STL" />
      </geometry>
      <material
        name="">
        <color
          rgba="1 0.501960784313725 0.501960784313725 1" />
      </material>
    </visual>
    <collision>
      <origin
        xyz="0 0 0"
        rpy="0 0 0" />
      <geometry>
        <mesh
          filename="package://grape_robot_description/meshes/arm2_link3.STL" />
      </geometry>
    </collision>
  </link>
  <joint
    name="arm2_joint3"
    type="revolute">
    <origin
      xyz="1.2 0 0.0525"
      rpy="0 0 0" />
    <parent
      link="arm2_link2" />
    <child
      link="arm2_link3" />
    <axis
      xyz="0 0 -1" />
    <limit
      lower="-2.3"
      upper="2.3"
      effort="1000"
      velocity="10" />
  </joint>

<!--arm2_link4-->
  <link
    name="arm2_link4">
    <inertial>
      <origin
        xyz="0 -0.00302605180463056 -0.0383650785949965"
        rpy="0 0 0" />
      <mass
        value="1.57381909523614" />
      <inertia
        ixx="0.00391501227913987"
        ixy="3.33693696071095E-20"
        ixz="1.23177268349141E-19"
        iyy="0.00392883927742792"
        iyz="-5.5410825842882E-05"
        izz="0.00364961256262643" />
    </inertial>
    <visual>
      <origin
        xyz="0 0 0"
        rpy="0 0 0" />
      <geometry>
        <mesh
          filename="package://grape_robot_description/meshes/arm2_link4.STL" />
      </geometry>
      <material
        name="">
        <color
          rgba="1 0.501960784313725 0.501960784313725 1" />
      </material>
    </visual>
    <collision>
      <origin
        xyz="0 0 0"
        rpy="0 0 0" />
      <geometry>
        <mesh
          filename="package://grape_robot_description/meshes/arm2_link4.STL" />
      </geometry>
    </collision>
  </link>
  <joint
    name="arm2_joint4"
    type="revolute">
    <origin
      xyz="0.9 0 -0.0775"
      rpy="0 0 0" />
    <parent
      link="arm2_link3" />
    <child
      link="arm2_link4" />
    <axis
      xyz="0 0 -1" />
    <limit
      lower="-1.57"
      upper="1.57"
      effort="100"
      velocity="10" />
  </joint>

<!--arm2_link5-->
  <link
    name="arm2_link5">
    <inertial>
      <origin
        xyz="-0.00758695627207703 2.22044604925031E-16 0.056641504407962"
        rpy="0 0 0" />
      <mass
        value="0.848992580818122" />
      <inertia
        ixx="0.0017174124569853"
        ixy="3.2679329400357E-20"
        ixz="0.000118252019301431"
        iyy="0.00151439261603278"
        iyz="-8.09576373533299E-21"
        izz="0.0010707437144987" />
    </inertial>
    <visual>
      <origin
        xyz="0 0 0"
        rpy="0 0 0" />
      <geometry>
        <mesh
          filename="package://grape_robot_description/meshes/arm2_link5.STL" />
      </geometry>
      <material
        name="">
        <color
          rgba="0.96078431372549 0.117647058823529 0 1" />
      </material>
    </visual>
    <collision>
      <origin
        xyz="0 0 0"
        rpy="0 0 0" />
      <geometry>
        <mesh
          filename="package://grape_robot_description/meshes/arm2_link5.STL" />
      </geometry>
    </collision>
  </link>
  <joint
    name="arm2_joint5"
    type="continuous">
    <origin
      xyz="0 0.05 -0.05"
      rpy="-1.5708 0 0" />
    <parent
      link="arm2_link4" />
    <child
      link="arm2_link5" />
    <axis
      xyz="0 0 1" />
  </joint>

<!--arm2_end_effector-->
  <link
    name="arm2_end_effector">
    <inertial>
      <origin
        xyz="0.0347525005713431 2.22044604925031E-16 -0.000144066831606171"
        rpy="0 0 0" />
      <mass
        value="0.306982526837746" />
      <inertia
        ixx="0.000216244705183095"
        ixy="2.36798510977976E-20"
        ixz="1.49251690973179E-06"
        iyy="0.000231480290788856"
        iyz="2.76558766607602E-21"
        izz="0.000232187474288551" />
    </inertial>
    <visual>
      <origin
        xyz="0 0 0"
        rpy="0 0 0" />
      <geometry>
        <mesh
          filename="package://grape_robot_description/meshes/arm2_end_effector.STL" />
      </geometry>
      <material
        name="">
        <color
          rgba="0.752941176470588 0 0.752941176470588 1" />
      </material>
    </visual>
    <collision>
      <origin
        xyz="0 0 0"
        rpy="0 0 0" />
      <geometry>
        <mesh
          filename="package://grape_robot_description/meshes/arm2_end_effector.STL" />
      </geometry>
    </collision>
  </link>
  <joint
    name="arm2_endjoint"
    type="fixed">
    <origin
      xyz="0.017042 0 0.075"
      rpy="-0.02537 0 0" />
    <parent
      link="arm2_link5" />
    <child
      link="arm2_end_effector" />
    <axis
      xyz="0 0 0" />
  </joint>

<!--camera-->
  <link name="camera">
    <collision>
      <origin xyz="0 0 0" rpy="0 0 0"/>
      <geometry>
        <box size="${cameraLength} ${cameraWidth} ${cameraHeight}"/>
      </geometry>
    </collision>

    <visual>
      <origin xyz="0 0 0" rpy="0 0 0"/>
      <geometry>
        <box size="${cameraLength} ${cameraWidth} ${cameraHeight}"/>
      </geometry>
      <material name="green"/>
    </visual>

    <inertial>
      <mass value="${cameraMass}" />
      <origin xyz="0 0 0" rpy="0 0 0"/>
      <box_inertia m="${cameraMass}" x="${cameraLength}" y="${cameraWidth}" z="${cameraHeight}" />
      <inertia ixx="1e-6" ixy="0" ixz="0" iyy="1e-6" iyz="0" izz="1e-6" />
    </inertial>
  </link>

  <joint name="camera_joint" type="fixed">
    <axis xyz="0 1 0" />
    <origin xyz="0.07 0 0.02" rpy="0 0 0"/>
    <parent link="arm2_end_effector"/>
    <child link="camera"/>
  </joint>

<!--for camera frame adjustment-->
  <link name="camera_link_optical">
  </link>

  <joint name="camera_optical_joint" type="fixed">
    <origin xyz="0 0 0" rpy="-1.57 0 -1.57"/>
    <parent link="camera"/>
    <child link="camera_link_optical"/>
  </joint>

<!--transmission block-->
<transmission name="trans_wheel_joint1">
        <type>transmission_interface/SimpleTransmission</type>
        <joint name="wheel_joint1">
            <hardwareInterface>hardware_interface/VelocityJointInterface</hardwareInterface>
        </joint>
        <actuator name="wheel_joint1_motor">
            <hardwareInterface>hardware_interface/VelocityJointInterface</hardwareInterface>
            <mechanicalReduction>1</mechanicalReduction>
        </actuator>
    </transmission>
    <transmission name="trans_wheel_joint2">
        <type>transmission_interface/SimpleTransmission</type>
        <joint name="wheel_joint2">
            <hardwareInterface>hardware_interface/VelocityJointInterface</hardwareInterface>
        </joint>
        <actuator name="wheel_joint2_motor">
            <hardwareInterface>hardware_interface/VelocityJointInterface</hardwareInterface>
            <mechanicalReduction>1</mechanicalReduction>
        </actuator>
    </transmission>
    <transmission name="trans_wheel_joint3">
        <type>transmission_interface/SimpleTransmission</type>
        <joint name="wheel_joint3">
            <hardwareInterface>hardware_interface/VelocityJointInterface</hardwareInterface>
        </joint>
        <actuator name="wheel_joint3_motor">
            <hardwareInterface>hardware_interface/VelocityJointInterface</hardwareInterface>
            <mechanicalReduction>1</mechanicalReduction>
        </actuator>
    </transmission>
    <transmission name="trans_wheel_joint4">
        <type>transmission_interface/SimpleTransmission</type>
        <joint name="wheel_joint4">
            <hardwareInterface>hardware_interface/VelocityJointInterface</hardwareInterface>
        </joint>
        <actuator name="wheel_joint4_motor">
            <hardwareInterface>hardware_interface/VelocityJointInterface</hardwareInterface>
            <mechanicalReduction>1</mechanicalReduction>
        </actuator>
    </transmission>
    <transmission name="trans_arm1_joint1">
        <type>transmission_interface/SimpleTransmission</type>
        <joint name="arm1_joint1">
            <hardwareInterface>hardware_interface/PositionJointInterface</hardwareInterface>
        </joint>
        <actuator name="arm1_joint1_motor">
            <hardwareInterface>hardware_interface/PositionJointInterface</hardwareInterface>
            <mechanicalReduction>1</mechanicalReduction>
        </actuator>
    </transmission>
    <transmission name="trans_arm1_joint2">
        <type>transmission_interface/SimpleTransmission</type>
        <joint name="arm1_joint2">
            <hardwareInterface>hardware_interface/PositionJointInterface</hardwareInterface>
        </joint>
        <actuator name="arm1_joint2_motor">
            <hardwareInterface>hardware_interface/PositionJointInterface</hardwareInterface>
            <mechanicalReduction>1</mechanicalReduction>
        </actuator>
    </transmission>
    <transmission name="trans_arm1_joint3">
        <type>transmission_interface/SimpleTransmission</type>
        <joint name="arm1_joint3">
            <hardwareInterface>hardware_interface/PositionJointInterface</hardwareInterface>
        </joint>
        <actuator name="arm1_joint3_motor">
            <hardwareInterface>hardware_interface/PositionJointInterface</hardwareInterface>
            <mechanicalReduction>1</mechanicalReduction>
        </actuator>
    </transmission>
    <transmission name="trans_arm1_joint4">
        <type>transmission_interface/SimpleTransmission</type>
        <joint name="arm1_joint4">
            <hardwareInterface>hardware_interface/PositionJointInterface</hardwareInterface>
        </joint>
        <actuator name="arm1_joint4_motor">
            <hardwareInterface>hardware_interface/PositionJointInterface</hardwareInterface>
            <mechanicalReduction>1</mechanicalReduction>
        </actuator>
    </transmission>
    <transmission name="trans_grip_rightjoint">
        <type>transmission_interface/SimpleTransmission</type>
        <joint name="grip_rightjoint">
            <hardwareInterface>hardware_interface/PositionJointInterface</hardwareInterface>
        </joint>
        <actuator name="grip_rightjoint_motor">
            <hardwareInterface>hardware_interface/PositionJointInterface</hardwareInterface>
            <mechanicalReduction>1</mechanicalReduction>
        </actuator>
    </transmission>
    <transmission name="trans_grip_leftjoint">
        <type>transmission_interface/SimpleTransmission</type>
        <joint name="grip_leftjoint">
            <hardwareInterface>hardware_interface/PositionJointInterface</hardwareInterface>
        </joint>
        <actuator name="grip_leftjoint_motor">
            <hardwareInterface>hardware_interface/PositionJointInterface</hardwareInterface>
            <mechanicalReduction>1</mechanicalReduction>
        </actuator>
    </transmission>
    <transmission name="trans_arm2_joint1">
        <type>transmission_interface/SimpleTransmission</type>
        <joint name="arm2_joint1">
            <hardwareInterface>hardware_interface/PositionJointInterface</hardwareInterface>
        </joint>
        <actuator name="arm2_joint1_motor">
            <hardwareInterface>hardware_interface/PositionJointInterface</hardwareInterface>
            <mechanicalReduction>1</mechanicalReduction>
        </actuator>
    </transmission>
    <transmission name="trans_arm2_joint2">
        <type>transmission_interface/SimpleTransmission</type>
        <joint name="arm2_joint2">
            <hardwareInterface>hardware_interface/PositionJointInterface</hardwareInterface>
        </joint>
        <actuator name="arm2_joint2_motor">
            <hardwareInterface>hardware_interface/PositionJointInterface</hardwareInterface>
            <mechanicalReduction>1</mechanicalReduction>
        </actuator>
    </transmission>
    <transmission name="trans_arm2_joint3">
        <type>transmission_interface/SimpleTransmission</type>
        <joint name="arm2_joint3">
            <hardwareInterface>hardware_interface/PositionJointInterface</hardwareInterface>
        </joint>
        <actuator name="arm2_joint3_motor">
            <hardwareInterface>hardware_interface/PositionJointInterface</hardwareInterface>
            <mechanicalReduction>1</mechanicalReduction>
        </actuator>
    </transmission>
    <transmission name="trans_arm2_joint4">
        <type>transmission_interface/SimpleTransmission</type>
        <joint name="arm2_joint4">
            <hardwareInterface>hardware_interface/PositionJointInterface</hardwareInterface>
        </joint>
        <actuator name="arm2_joint4_motor">
            <hardwareInterface>hardware_interface/PositionJointInterface</hardwareInterface>
            <mechanicalReduction>1</mechanicalReduction>
        </actuator>
    </transmission>
    <transmission name="trans_arm2_joint5">
        <type>transmission_interface/SimpleTransmission</type>
        <joint name="arm2_joint5">
            <hardwareInterface>hardware_interface/PositionJointInterface</hardwareInterface>
        </joint>
        <actuator name="arm2_joint5_motor">
            <hardwareInterface>hardware_interface/PositionJointInterface</hardwareInterface>
            <mechanicalReduction>1</mechanicalReduction>
        </actuator>
    </transmission>


<!--gazebo plugin-->
    <gazebo>
        <plugin name="gazebo_ros_control" filename="libgazebo_ros_control.so">
            <robotNamespace>/</robotNamespace>
		<legacyModeNS>true</legacyModeNS>
        </plugin>
    </gazebo>
</robot>
